Workbook
Name NativeTimeline_Date: #N/A
Name Slicer_Category: #N/A

Sheet Raw_orders
A1: OrderID | B1: Date | C1: Cust_ID | D1: Prod_ID | E1: Qty | F1: Ship_Date | G1: Region | H1: Promo_Code | I1: Product_name | J1: Category | K1: Unit_cost | L1: Unit_price | M1: Clean_name | N1: Membership_tier | O1: Total_Revenue | P1: Total_Profit | Q1: Days_to_ship | R1: Status | S1: Remark | T1: Promo_valid?
A2: ORD-24-1001 | B2: 45294 | C2: C-001 | D2: P-500 | E2: 5 | F2: 45296 | G2: North | H2: WELCOME10 | I2: =VLOOKUP(D2,Product_Master!$A$1:$F$8,2,FALSE) -> Wireless Mouse X1 | J2: =INDEX(Product_Master!$A$1:$F$8,MATCH(Raw_orders!D2,Product_Master!$A$1:$A$8,0),3) -> Electronics | K2: =_xlfn.XLOOKUP(D2,Product_Master!A:A,Product_Master!D:D,"Not Found",0) -> 12.5 | L2: =_xlfn.XLOOKUP(D2,Product_Master!A:A,Product_Master!E:E,"Not Found") -> 39.99 | M2: =IFERROR(VLOOKUP(C2,Customer_database!$A$1:$F$11,5,FALSE),"Unknown Item") -> John Smith | N2: =INDEX(Customer_database!$A$1:$F$11,MATCH(Raw_orders!C2,Customer_database!$A$1:$A$11,0),4) -> Gold | O2: =E2*L2 -> 199.95 | P2: =(L2-K2)*E2 -> 137.45 | Q2: =F2-B2 -> 2 | R2: =IF(Q2>5,"Late","On-time") -> On-time | S2: =IF(AND(Table1[[#This Row],[Status]]="Late",Table1[[#This Row],[Region]]="North"),"CRITICAL DELAY","NORMAL") -> NORMAL | T2: =OR(H2="WELCOME10",H2="FREESHIP") -> TRUE
A3: ORD-24-1002 | B3: 45295 | C3: C-003 | D3: P-502 | E3: 1 | F3: 45299 | G3: West | I3: =VLOOKUP(D3,Product_Master!$A$1:$F$8,2,FALSE) -> Ergo Office Chair | J3: =INDEX(Product_Master!$A$1:$F$8,MATCH(Raw_orders!D3,Product_Master!$A$1:$A$8,0),3) -> Furniture | K3: =_xlfn.XLOOKUP(D3,Product_Master!A:A,Product_Master!D:D,"Not Found",0) -> 85 | L3: =_xlfn.XLOOKUP(D3,Product_Master!A:A,Product_Master!E:E,"Not Found") -> 249.99 | M3: =IFERROR(VLOOKUP(C3,Customer_database!$A$1:$F$11,5,FALSE),"Unknown Item") -> Emily Blunt | N3: =INDEX(Customer_database!$A$1:$F$11,MATCH(Raw_orders!C3,Customer_database!$A$1:$A$11,0),4) -> Bronze | O3: =E3*L3 -> 249.99 | P3: =(L3-K3)*E3 -> 164.99 | Q3: =F3-B3 -> 4 | R3: =IF(Q3>5,"Late","On-time") -> On-time | S3: =IF(AND(Table1[[#This Row],[Status]]="Late",Table1[[#This Row],[Region]]="North"),"CRITICAL DELAY","NORMAL") -> NORMAL | T3: =OR(H3="WELCOME10",H3="FREESHIP") -> FALSE
A4: ORD-24-1003 | B4: 45297 | C4: C-002 | D4: P-501 | E4: 10 | F4: 45305 | G4: East | H4: BULK25 | I4: =VLOOKUP(D4,Product_Master!$A$1:$F$8,2,FALSE) -> Mech Keyboard RGB | J4: =INDEX(Product_Master!$A$1:$F$8,MATCH(Raw_orders!D4,Product_Master!$A$1:$A$8,0),3) -> Electronics | K4: =_xlfn.XLOOKUP(D4,Product_Master!A:A,Product_Master!D:D,"Not Found",0) -> 45 | L4: =_xlfn.XLOOKUP(D4,Product_Master!A:A,Product_Master!E:E,"Not Found") -> 129.99 | M4: =IFERROR(VLOOKUP(C4,Customer_database!$A$1:$F$11,5,FALSE),"Unknown Item") -> Sarah Connor | N4: =INDEX(Customer_database!$A$1:$F$11,MATCH(Raw_orders!C4,Customer_database!$A$1:$A$11,0),4) -> Silver | O4: =E4*L4 -> 1299.9 | P4: =(L4-K4)*E4 -> 849.9 | Q4: =F4-B4 -> 8 | R4: =IF(Q4>5,"Late","On-time") -> Late | S4: =IF(AND(Table1[[#This Row],[Status]]="Late",Table1[[#This Row],[Region]]="North"),"CRITICAL DELAY","NORMAL") -> NORMAL | T4: =OR(H4="WELCOME10",H4="FREESHIP") -> FALSE
A5: ORD-24-1004 | B5: 45299 | C5: C-005 | D5: P-505 | E5: 2 | F5: 45300 | G5: North | I5: =VLOOKUP(D5,Product_Master!$A$1:$F$8,2,FALSE) -> Dual Monitor Arm | J5: =INDEX(Product_Master!$A$1:$F$8,MATCH(Raw_orders!D5,Product_Master!$A$1:$A$8,0),3) -> Electronics | K5: =_xlfn.XLOOKUP(D5,Product_Master!A:A,Product_Master!D:D,"Not Found",0) -> 25 | L5: =_xlfn.XLOOKUP(D5,Product_Master!A:A,Product_Master!E:E,"Not Found") -> 75 | M5: =IFERROR(VLOOKUP(C5,Customer_database!$A$1:$F$11,5,FALSE),"Unknown Item") -> Dwight Schrute | N5: =INDEX(Customer_database!$A$1:$F$11,MATCH(Raw_orders!C5,Customer_database!$A$1:$A$11,0),4) -> Silver | O5: =E5*L5 -> 150 | P5: =(L5-K5)*E5 -> 100 | Q5: =F5-B5 -> 1 | R5: =IF(Q5>5,"Late","On-time") -> On-time | S5: =IF(AND(Table1[[#This Row],[Status]]="Late",Table1[[#This Row],[Region]]="North"),"CRITICAL DELAY","NORMAL") -> NORMAL | T5: =OR(H5="WELCOME10",H5="FREESHIP") -> FALSE
A6: ORD-24-1005 | B6: 45301 | C6: C-001 | D6: P-500 | E6: 1 | F6: 45303 | G6: North | H6: FREESHIP | I6: =VLOOKUP(D6,Product_Master!$A$1:$F$8,2,FALSE) -> Wireless Mouse X1 | J6: =INDEX(Product_Master!$A$1:$F$8,MATCH(Raw_orders!D6,Product_Master!$A$1:$A$8,0),3) -> Electronics | K6: =_xlfn.XLOOKUP(D6,Product_Master!A:A,Product_Master!D:D,"Not Found",0) -> 12.5 | L6: =_xlfn.XLOOKUP(D6,Product_Master!A:A,Product_Master!E:E,"Not Found") -> 39.99 | M6: =IFERROR(VLOOKUP(C6,Customer_database!$A$1:$F$11,5,FALSE),"Unknown Item") -> John Smith | N6: =INDEX(Customer_database!$A$1:$F$11,MATCH(Raw_orders!C6,Customer_database!$A$1:$A$11,0),4) -> Gold | O6: =E6*L6 -> 39.99 | P6: =(L6-K6)*E6 -> 27.49 | Q6: =F6-B6 -> 2 | R6: =IF(Q6>5,"Late","On-time") -> On-time | S6: =IF(AND(Table1[[#This Row],[Status]]="Late",Table1[[#This Row],[Region]]="North"),"CRITICAL DELAY","NORMAL") -> NORMAL | T6: =OR(H6="WELCOME10",H6="FREESHIP") -> TRUE
A7: ORD-24-1006 | B7: 45303 | C7: C-004 | D7: P-503 | E7: 3 | F7: 45310 | G7: South | H7: WELCOME10 | I7: =VLOOKUP(D7,Product_Master!$A$1:$F$8,2,FALSE) -> Oak Standing Desk | J7: =INDEX(Product_Master!$A$1:$F$8,MATCH(Raw_orders!D7,Product_Master!$A$1:$A$8,0),3) -> Furniture | K7: =_xlfn.XLOOKUP(D7,Product_Master!A:A,Product_Master!D:D,"Not Found",0) -> 160 | L7: =_xlfn.XLOOKUP(D7,Product_Master!A:A,Product_Master!E:E,"Not Found") -> 450 | M7: =IFERROR(VLOOKUP(C7,Customer_database!$A$1:$F$11,5,FALSE),"Unknown Item") -> Michael Scott | N7: =INDEX(Customer_database!$A$1:$F$11,MATCH(Raw_orders!C7,Customer_database!$A$1:$A$11,0),4) -> Gold | O7: =E7*L7 -> 1350 | P7: =(L7-K7)*E7 -> 870 | Q7: =F7-B7 -> 7 | R7: =IF(Q7>5,"Late","On-time") -> Late | S7: =IF(AND(Table1[[#This Row],[Status]]="Late",Table1[[#This Row],[Region]]="North"),"CRITICAL DELAY","NORMAL") -> NORMAL | T7: =OR(H7="WELCOME10",H7="FREESHIP") -> TRUE
A8: ORD-24-1007 | B8: 45306 | C8: C-006 | D8: P-504 | E8: 4 | F8: 45313 | G8: West | I8: =VLOOKUP(D8,Product_Master!$A$1:$F$8,2,FALSE) -> Smart LED Lamp | J8: =INDEX(Product_Master!$A$1:$F$8,MATCH(Raw_orders!D8,Product_Master!$A$1:$A$8,0),3) -> Home Decor | K8: =_xlfn.XLOOKUP(D8,Product_Master!A:A,Product_Master!D:D,"Not Found",0) -> 15 | L8: =_xlfn.XLOOKUP(D8,Product_Master!A:A,Product_Master!E:E,"Not Found") -> 45 | M8: =IFERROR(VLOOKUP(C8,Customer_database!$A$1:$F$11,5,FALSE),"Unknown Item") -> Jim Halpert | N8: =INDEX(Customer_database!$A$1:$F$11,MATCH(Raw_orders!C8,Customer_database!$A$1:$A$11,0),4) -> Bronze | O8: =E8*L8 -> 180 | P8: =(L8-K8)*E8 -> 120 | Q8: =F8-B8 -> 7 | R8: =IF(Q8>5,"Late","On-time") -> Late | S8: =IF(AND(Table1[[#This Row],[Status]]="Late",Table1[[#This Row],[Region]]="North"),"CRITICAL DELAY","NORMAL") -> NORMAL | T8: =OR(H8="WELCOME10",H8="FREESHIP") -> FALSE
A9: ORD-24-1008 | B9: 45307 | C9: C-002 | D9: P-501 | E9: 6 | F9: 45309 | G9: East | I9: =VLOOKUP(D9,Product_Master!$A$1:$F$8,2,FALSE) -> Mech Keyboard RGB | J9: =INDEX(Product_Master!$A$1:$F$8,MATCH(Raw_orders!D9,Product_Master!$A$1:$A$8,0),3) -> Electronics | K9: =_xlfn.XLOOKUP(D9,Product_Master!A:A,Product_Master!D:D,"Not Found",0) -> 45 | L9: =_xlfn.XLOOKUP(D9,Product_Master!A:A,Product_Master!E:E,"Not Found") -> 129.99 | M9: =IFERROR(VLOOKUP(C9,Customer_database!$A$1:$F$11,5,FALSE),"Unknown Item") -> Sarah Connor | N9: =INDEX(Customer_database!$A$1:$F$11,MATCH(Raw_orders!C9,Customer_database!$A$1:$A$11,0),4) -> Silver | O9: =E9*L9 -> 779.94 | P9: =(L9-K9)*E9 -> 509.94 | Q9: =F9-B9 -> 2 | R9: =IF(Q9>5,"Late","On-time") -> On-time | S9: =IF(AND(Table1[[#This Row],[Status]]="Late",Table1[[#This Row],[Region]]="North"),"CRITICAL DELAY","NORMAL") -> NORMAL | T9: =OR(H9="WELCOME10",H9="FREESHIP") -> FALSE
A10: ORD-24-1009 | B10: 45309 | C10: C-008 | D10: P-502 | E10: 2 | F10: 45320 | G10: South | H10: LATE_SORRY | I10: =VLOOKUP(D10,Product_Master!$A$1:$F$8,2,FALSE) -> Ergo Office Chair | J10: =INDEX(Product_Master!$A$1:$F$8,MATCH(Raw_orders!D10,Product_Master!$A$1:$A$8,0),3) -> Furniture | K10: =_xlfn.XLOOKUP(D10,Product_Master!A:A,Product_Master!D:D,"Not Found",0) -> 85 | L10: =_xlfn.XLOOKUP(D10,Product_Master!A:A,Product_Master!E:E,"Not Found") -> 249.99 | M10: =IFERROR(VLOOKUP(C10,Customer_database!$A$1:$F$11,5,FALSE),"Unknown Item") -> Ryan Howard | N10: =INDEX(Customer_database!$A$1:$F$11,MATCH(Raw_orders!C10,Customer_database!$A$1:$A$11,0),4) -> Bronze | O10: =E10*L10 -> 499.98 | P10: =(L10-K10)*E10 -> 329.98 | Q10: =F10-B10 -> 11 | R10: =IF(Q10>5,"Late","On-time") -> Late | S10: =IF(AND(Table1[[#This Row],[Status]]="Late",Table1[[#This Row],[Region]]="North"),"CRITICAL DELAY","NORMAL") -> NORMAL | T10: =OR(H10="WELCOME10",H10="FREESHIP") -> FALSE
A11: ORD-24-1010 | B11: 45311 | C11: C-003 | D11: P-505 | E11: 1 | F11: 45312 | G11: West | I11: =VLOOKUP(D11,Product_Master!$A$1:$F$8,2,FALSE) -> Dual Monitor Arm | J11: =INDEX(Product_Master!$A$1:$F$8,MATCH(Raw_orders!D11,Product_Master!$A$1:$A$8,0),3) -> Electronics | K11: =_xlfn.XLOOKUP(D11,Product_Master!A:A,Product_Master!D:D,"Not Found",0) -> 25 | L11: =_xlfn.XLOOKUP(D11,Product_Master!A:A,Product_Master!E:E,"Not Found") -> 75 | M11: =IFERROR(VLOOKUP(C11,Customer_database!$A$1:$F$11,5,FALSE),"Unknown Item") -> Emily Blunt | N11: =INDEX(Customer_database!$A$1:$F$11,MATCH(Raw_orders!C11,Customer_database!$A$1:$A$11,0),4) -> Bronze | O11: =E11*L11 -> 75 | P11: =(L11-K11)*E11 -> 50 | Q11: =F11-B11 -> 1 | R11: =IF(Q11>5,"Late","On-time") -> On-time | S11: =IF(AND(Table1[[#This Row],[Status]]="Late",Table1[[#This Row],[Region]]="North"),"CRITICAL DELAY","NORMAL") -> NORMAL | T11: =OR(H11="WELCOME10",H11="FREESHIP") -> FALSE
A12: ORD-24-1011 | B12: 45313 | C12: C-009 | D12: P-500 | E12: 20 | F12: 45314 | G12: North | H12: BULK_VIP | I12: =VLOOKUP(D12,Product_Master!$A$1:$F$8,2,FALSE) -> Wireless Mouse X1 | J12: =INDEX(Product_Master!$A$1:$F$8,MATCH(Raw_orders!D12,Product_Master!$A$1:$A$8,0),3) -> Electronics | K12: =_xlfn.XLOOKUP(D12,Product_Master!A:A,Product_Master!D:D,"Not Found",0) -> 12.5 | L12: =_xlfn.XLOOKUP(D12,Product_Master!A:A,Product_Master!E:E,"Not Found") -> 39.99 | M12: =IFERROR(VLOOKUP(C12,Customer_database!$A$1:$F$11,5,FALSE),"Unknown Item") -> Creed Bratton | N12: =INDEX(Customer_database!$A$1:$F$11,MATCH(Raw_orders!C12,Customer_database!$A$1:$A$11,0),4) -> Gold | O12: =E12*L12 -> 799.8 | P12: =(L12-K12)*E12 -> 549.8 | Q12: =F12-B12 -> 1 | R12: =IF(Q12>5,"Late","On-time") -> On-time | S12: =IF(AND(Table1[[#This Row],[Status]]="Late",Table1[[#This Row],[Region]]="North"),"CRITICAL DELAY","NORMAL") -> NORMAL | T12: =OR(H12="WELCOME10",H12="FREESHIP") -> FALSE
A13: ORD-24-1012 | B13: 45316 | C13: C-007 | D13: P-502 | E13: 3 | F13: 45327 | G13: East | I13: =VLOOKUP(D13,Product_Master!$A$1:$F$8,2,FALSE) -> Ergo Office Chair | J13: =INDEX(Product_Master!$A$1:$F$8,MATCH(Raw_orders!D13,Product_Master!$A$1:$A$8,0),3) -> Furniture | K13: =_xlfn.XLOOKUP(D13,Product_Master!A:A,Product_Master!D:D,"Not Found",0) -> 85 | L13: =_xlfn.XLOOKUP(D13,Product_Master!A:A,Product_Master!E:E,"Not Found") -> 249.99 | M13: =IFERROR(VLOOKUP(C13,Customer_database!$A$1:$F$11,5,FALSE),"Unknown Item") -> Pam Beesly | N13: =INDEX(Customer_database!$A$1:$F$11,MATCH(Raw_orders!C13,Customer_database!$A$1:$A$11,0),4) -> Silver | O13: =E13*L13 -> 749.97 | P13: =(L13-K13)*E13 -> 494.97 | Q13: =F13-B13 -> 11 | R13: =IF(Q13>5,"Late","On-time") -> Late | S13: =IF(AND(Table1[[#This Row],[Status]]="Late",Table1[[#This Row],[Region]]="North"),"CRITICAL DELAY","NORMAL") -> NORMAL | T13: =OR(H13="WELCOME10",H13="FREESHIP") -> FALSE
A14: ORD-24-1013 | B14: 45317 | C14: C-010 | D14: P-503 | E14: 2 | F14: 45319 | G14: South | H14: WELCOME10 | I14: =VLOOKUP(D14,Product_Master!$A$1:$F$8,2,FALSE) -> Oak Standing Desk | J14: =INDEX(Product_Master!$A$1:$F$8,MATCH(Raw_orders!D14,Product_Master!$A$1:$A$8,0),3) -> Furniture | K14: =_xlfn.XLOOKUP(D14,Product_Master!A:A,Product_Master!D:D,"Not Found",0) -> 160 | L14: =_xlfn.XLOOKUP(D14,Product_Master!A:A,Product_Master!E:E,"Not Found") -> 450 | M14: =IFERROR(VLOOKUP(C14,Customer_database!$A$1:$F$11,5,FALSE),"Unknown Item") -> Stanley Hudson | N14: =INDEX(Customer_database!$A$1:$F$11,MATCH(Raw_orders!C14,Customer_database!$A$1:$A$11,0),4) -> Silver | O14: =E14*L14 -> 900 | P14: =(L14-K14)*E14 -> 580 | Q14: =F14-B14 -> 2 | R14: =IF(Q14>5,"Late","On-time") -> On-time | S14: =IF(AND(Table1[[#This Row],[Status]]="Late",Table1[[#This Row],[Region]]="North"),"CRITICAL DELAY","NORMAL") -> NORMAL | T14: =OR(H14="WELCOME10",H14="FREESHIP") -> TRUE
A15: ORD-24-1014 | B15: 45319 | C15: C-005 | D15: P-504 | E15: 1 | F15: 45324 | G15: North | I15: =VLOOKUP(D15,Product_Master!$A$1:$F$8,2,FALSE) -> Smart LED Lamp | J15: =INDEX(Product_Master!$A$1:$F$8,MATCH(Raw_orders!D15,Product_Master!$A$1:$A$8,0),3) -> Home Decor | K15: =_xlfn.XLOOKUP(D15,Product_Master!A:A,Product_Master!D:D,"Not Found",0) -> 15 | L15: =_xlfn.XLOOKUP(D15,Product_Master!A:A,Product_Master!E:E,"Not Found") -> 45 | M15: =IFERROR(VLOOKUP(C15,Customer_database!$A$1:$F$11,5,FALSE),"Unknown Item") -> Dwight Schrute | N15: =INDEX(Customer_database!$A$1:$F$11,MATCH(Raw_orders!C15,Customer_database!$A$1:$A$11,0),4) -> Silver | O15: =E15*L15 -> 45 | P15: =(L15-K15)*E15 -> 30 | Q15: =F15-B15 -> 5 | R15: =IF(Q15>5,"Late","On-time") -> On-time | S15: =IF(AND(Table1[[#This Row],[Status]]="Late",Table1[[#This Row],[Region]]="North"),"CRITICAL DELAY","NORMAL") -> NORMAL | T15: =OR(H15="WELCOME10",H15="FREESHIP") -> FALSE
A16: ORD-24-1015 | B16: 45321 | C16: C-001 | D16: P-501 | E16: 5 | F16: 45323 | G16: North | H16: FREESHIP | I16: =VLOOKUP(D16,Product_Master!$A$1:$F$8,2,FALSE) -> Mech Keyboard RGB | J16: =INDEX(Product_Master!$A$1:$F$8,MATCH(Raw_orders!D16,Product_Master!$A$1:$A$8,0),3) -> Electronics | K16: =_xlfn.XLOOKUP(D16,Product_Master!A:A,Product_Master!D:D,"Not Found",0) -> 45 | L16: =_xlfn.XLOOKUP(D16,Product_Master!A:A,Product_Master!E:E,"Not Found") -> 129.99 | M16: =IFERROR(VLOOKUP(C16,Customer_database!$A$1:$F$11,5,FALSE),"Unknown Item") -> John Smith | N16: =INDEX(Customer_database!$A$1:$F$11,MATCH(Raw_orders!C16,Customer_database!$A$1:$A$11,0),4) -> Gold | O16: =E16*L16 -> 649.95 | P16: =(L16-K16)*E16 -> 424.95 | Q16: =F16-B16 -> 2 | R16: =IF(Q16>5,"Late","On-time") -> On-time | S16: =IF(AND(Table1[[#This Row],[Status]]="Late",Table1[[#This Row],[Region]]="North"),"CRITICAL DELAY","NORMAL") -> NORMAL | T16: =OR(H16="WELCOME10",H16="FREESHIP") -> TRUE
A17: ORD-24-1001 | B17: 45294 | C17: C-001 | D17: P-500 | E17: 5 | F17: 45296 | G17: North | H17: WELCOME10 | I17: =VLOOKUP(D17,Product_Master!$A$1:$F$8,2,FALSE) -> Wireless Mouse X1 | J17: =INDEX(Product_Master!$A$1:$F$8,MATCH(Raw_orders!D17,Product_Master!$A$1:$A$8,0),3) -> Electronics | K17: =_xlfn.XLOOKUP(D17,Product_Master!A:A,Product_Master!D:D,"Not Found",0) -> 12.5 | L17: =_xlfn.XLOOKUP(D17,Product_Master!A:A,Product_Master!E:E,"Not Found") -> 39.99 | M17: =IFERROR(VLOOKUP(C17,Customer_database!$A$1:$F$11,5,FALSE),"Unknown Item") -> John Smith | N17: =INDEX(Customer_database!$A$1:$F$11,MATCH(Raw_orders!C17,Customer_database!$A$1:$A$11,0),4) -> Gold | O17: =E17*L17 -> 199.95 | P17: =(L17-K17)*E17 -> 137.45 | Q17: =F17-B17 -> 2 | R17: =IF(Q17>5,"Late","On-time") -> On-time | S17: =IF(AND(Table1[[#This Row],[Status]]="Late",Table1[[#This Row],[Region]]="North"),"CRITICAL DELAY","NORMAL") -> NORMAL | T17: =OR(H17="WELCOME10",H17="FREESHIP") -> TRUE
A18: ORD-24-1002 | B18: 45295 | C18: C-003 | D18: P-502 | E18: 1 | F18: 45299 | G18: West | I18: =VLOOKUP(D18,Product_Master!$A$1:$F$8,2,FALSE) -> Ergo Office Chair | J18: =INDEX(Product_Master!$A$1:$F$8,MATCH(Raw_orders!D18,Product_Master!$A$1:$A$8,0),3) -> Furniture | K18: =_xlfn.XLOOKUP(D18,Product_Master!A:A,Product_Master!D:D,"Not Found",0) -> 85 | L18: =_xlfn.XLOOKUP(D18,Product_Master!A:A,Product_Master!E:E,"Not Found") -> 249.99 | M18: =IFERROR(VLOOKUP(C18,Customer_database!$A$1:$F$11,5,FALSE),"Unknown Item") -> Emily Blunt | N18: =INDEX(Customer_database!$A$1:$F$11,MATCH(Raw_orders!C18,Customer_database!$A$1:$A$11,0),4) -> Bronze | O18: =E18*L18 -> 249.99 | P18: =(L18-K18)*E18 -> 164.99 | Q18: =F18-B18 -> 4 | R18: =IF(Q18>5,"Late","On-time") -> On-time | S18: =IF(AND(Table1[[#This Row],[Status]]="Late",Table1[[#This Row],[Region]]="North"),"CRITICAL DELAY","NORMAL") -> NORMAL | T18: =OR(H18="WELCOME10",H18="FREESHIP") -> FALSE
A19: ORD-24-1003 | B19: 45297 | C19: C-002 | D19: P-501 | E19: 10 | F19: 45305 | G19: East | H19: BULK25 | I19: =VLOOKUP(D19,Product_Master!$A$1:$F$8,2,FALSE) -> Mech Keyboard RGB | J19: =INDEX(Product_Master!$A$1:$F$8,MATCH(Raw_orders!D19,Product_Master!$A$1:$A$8,0),3) -> Electronics | K19: =_xlfn.XLOOKUP(D19,Product_Master!A:A,Product_Master!D:D,"Not Found",0) -> 45 | L19: =_xlfn.XLOOKUP(D19,Product_Master!A:A,Product_Master!E:E,"Not Found") -> 129.99 | M19: =IFERROR(VLOOKUP(C19,Customer_database!$A$1:$F$11,5,FALSE),"Unknown Item") -> Sarah Connor | N19: =INDEX(Customer_database!$A$1:$F$11,MATCH(Raw_orders!C19,Customer_database!$A$1:$A$11,0),4) -> Silver | O19: =E19*L19 -> 1299.9 | P19: =(L19-K19)*E19 -> 849.9 | Q19: =F19-B19 -> 8 | R19: =IF(Q19>5,"Late","On-time") -> Late | S19: =IF(AND(Table1[[#This Row],[Status]]="Late",Table1[[#This Row],[Region]]="North"),"CRITICAL DELAY","NORMAL") -> NORMAL | T19: =OR(H19="WELCOME10",H19="FREESHIP") -> FALSE
A20: ORD-24-1004 | B20: 45299 | C20: C-005 | D20: P-505 | E20: 2 | F20: 45300 | G20: North | I20: =VLOOKUP(D20,Product_Master!$A$1:$F$8,2,FALSE) -> Dual Monitor Arm | J20: =INDEX(Product_Master!$A$1:$F$8,MATCH(Raw_orders!D20,Product_Master!$A$1:$A$8,0),3) -> Electronics | K20: =_xlfn.XLOOKUP(D20,Product_Master!A:A,Product_Master!D:D,"Not Found",0) -> 25 | L20: =_xlfn.XLOOKUP(D20,Product_Master!A:A,Product_Master!E:E,"Not Found") -> 75 | M20: =IFERROR(VLOOKUP(C20,Customer_database!$A$1:$F$11,5,FALSE),"Unknown Item") -> Dwight Schrute | N20: =INDEX(Customer_database!$A$1:$F$11,MATCH(Raw_orders!C20,Customer_database!$A$1:$A$11,0),4) -> Silver | O20: =E20*L20 -> 150 | P20: =(L20-K20)*E20 -> 100 | Q20: =F20-B20 -> 1 | R20: =IF(Q20>5,"Late","On-time") -> On-time | S20: =IF(AND(Table1[[#This Row],[Status]]="Late",Table1[[#This Row],[Region]]="North"),"CRITICAL DELAY","NORMAL") -> NORMAL | T20: =OR(H20="WELCOME10",H20="FREESHIP") -> FALSE
A21: ORD-24-1005 | B21: 45301 | C21: C-001 | D21: P-500 | E21: 1 | F21: 45303 | G21: North | H21: FREESHIP | I21: =VLOOKUP(D21,Product_Master!$A$1:$F$8,2,FALSE) -> Wireless Mouse X1 | J21: =INDEX(Product_Master!$A$1:$F$8,MATCH(Raw_orders!D21,Product_Master!$A$1:$A$8,0),3) -> Electronics | K21: =_xlfn.XLOOKUP(D21,Product_Master!A:A,Product_Master!D:D,"Not Found",0) -> 12.5 | L21: =_xlfn.XLOOKUP(D21,Product_Master!A:A,Product_Master!E:E,"Not Found") -> 39.99 | M21: =IFERROR(VLOOKUP(C21,Customer_database!$A$1:$F$11,5,FALSE),"Unknown Item") -> John Smith | N21: =INDEX(Customer_database!$A$1:$F$11,MATCH(Raw_orders!C21,Customer_database!$A$1:$A$11,0),4) -> Gold | O21: =E21*L21 -> 39.99 | P21: =(L21-K21)*E21 -> 27.49 | Q21: =F21-B21 -> 2 | R21: =IF(Q21>5,"Late","On-time") -> On-time | S21: =IF(AND(Table1[[#This Row],[Status]]="Late",Table1[[#This Row],[Region]]="North"),"CRITICAL DELAY","NORMAL") -> NORMAL | T21: =OR(H21="WELCOME10",H21="FREESHIP") -> TRUE
A22: ORD-24-1006 | B22: 45303 | C22: C-004 | D22: P-503 | E22: 3 | F22: 45310 | G22: South | H22: WELCOME10 | I22: =VLOOKUP(D22,Product_Master!$A$1:$F$8,2,FALSE) -> Oak Standing Desk | J22: =INDEX(Product_Master!$A$1:$F$8,MATCH(Raw_orders!D22,Product_Master!$A$1:$A$8,0),3) -> Furniture | K22: =_xlfn.XLOOKUP(D22,Product_Master!A:A,Product_Master!D:D,"Not Found",0) -> 160 | L22: =_xlfn.XLOOKUP(D22,Product_Master!A:A,Product_Master!E:E,"Not Found") -> 450 | M22: =IFERROR(VLOOKUP(C22,Customer_database!$A$1:$F$11,5,FALSE),"Unknown Item") -> Michael Scott | N22: =INDEX(Customer_database!$A$1:$F$11,MATCH(Raw_orders!C22,Customer_database!$A$1:$A$11,0),4) -> Gold | O22: =E22*L22 -> 1350 | P22: =(L22-K22)*E22 -> 870 | Q22: =F22-B22 -> 7 | R22: =IF(Q22>5,"Late","On-time") -> Late | S22: =IF(AND(Table1[[#This Row],[Status]]="Late",Table1[[#This Row],[Region]]="North"),"CRITICAL DELAY","NORMAL") -> NORMAL | T22: =OR(H22="WELCOME10",H22="FREESHIP") -> TRUE
A23: ORD-24-1007 | B23: 45306 | C23: C-006 | D23: P-504 | E23: 4 | F23: 45313 | G23: West | I23: =VLOOKUP(D23,Product_Master!$A$1:$F$8,2,FALSE) -> Smart LED Lamp | J23: =INDEX(Product_Master!$A$1:$F$8,MATCH(Raw_orders!D23,Product_Master!$A$1:$A$8,0),3) -> Home Decor | K23: =_xlfn.XLOOKUP(D23,Product_Master!A:A,Product_Master!D:D,"Not Found",0) -> 15 | L23: =_xlfn.XLOOKUP(D23,Product_Master!A:A,Product_Master!E:E,"Not Found") -> 45 | M23: =IFERROR(VLOOKUP(C23,Customer_database!$A$1:$F$11,5,FALSE),"Unknown Item") -> Jim Halpert | N23: =INDEX(Customer_database!$A$1:$F$11,MATCH(Raw_orders!C23,Customer_database!$A$1:$A$11,0),4) -> Bronze | O23: =E23*L23 -> 180 | P23: =(L23-K23)*E23 -> 120 | Q23: =F23-B23 -> 7 | R23: =IF(Q23>5,"Late","On-time") -> Late | S23: =IF(AND(Table1[[#This Row],[Status]]="Late",Table1[[#This Row],[Region]]="North"),"CRITICAL DELAY","NORMAL") -> NORMAL | T23: =OR(H23="WELCOME10",H23="FREESHIP") -> FALSE
A24: ORD-24-1008 | B24: 45307 | C24: C-002 | D24: P-501 | E24: 6 | F24: 45309 | G24: East | I24: =VLOOKUP(D24,Product_Master!$A$1:$F$8,2,FALSE) -> Mech Keyboard RGB | J24: =INDEX(Product_Master!$A$1:$F$8,MATCH(Raw_orders!D24,Product_Master!$A$1:$A$8,0),3) -> Electronics | K24: =_xlfn.XLOOKUP(D24,Product_Master!A:A,Product_Master!D:D,"Not Found",0) -> 45 | L24: =_xlfn.XLOOKUP(D24,Product_Master!A:A,Product_Master!E:E,"Not Found") -> 129.99 | M24: =IFERROR(VLOOKUP(C24,Customer_database!$A$1:$F$11,5,FALSE),"Unknown Item") -> Sarah Connor | N24: =INDEX(Customer_database!$A$1:$F$11,MATCH(Raw_orders!C24,Customer_database!$A$1:$A$11,0),4) -> Silver | O24: =E24*L24 -> 779.94 | P24: =(L24-K24)*E24 -> 509.94 | Q24: =F24-B24 -> 2 | R24: =IF(Q24>5,"Late","On-time") -> On-time | S24: =IF(AND(Table1[[#This Row],[Status]]="Late",Table1[[#This Row],[Region]]="North"),"CRITICAL DELAY","NORMAL") -> NORMAL | T24: =OR(H24="WELCOME10",H24="FREESHIP") -> FALSE
A25: ORD-24-1009 | B25: 45309 | C25: C-008 | D25: P-502 | E25: 2 | F25: 45320 | G25: South | H25: LATE_SORRY | I25: =VLOOKUP(D25,Product_Master!$A$1:$F$8,2,FALSE) -> Ergo Office Chair | J25: =INDEX(Product_Master!$A$1:$F$8,MATCH(Raw_orders!D25,Product_Master!$A$1:$A$8,0),3) -> Furniture | K25: =_xlfn.XLOOKUP(D25,Product_Master!A:A,Product_Master!D:D,"Not Found",0) -> 85 | L25: =_xlfn.XLOOKUP(D25,Product_Master!A:A,Product_Master!E:E,"Not Found") -> 249.99 | M25: =IFERROR(VLOOKUP(C25,Customer_database!$A$1:$F$11,5,FALSE),"Unknown Item") -> Ryan Howard | N25: =INDEX(Customer_database!$A$1:$F$11,MATCH(Raw_orders!C25,Customer_database!$A$1:$A$11,0),4) -> Bronze | O25: =E25*L25 -> 499.98 | P25: =(L25-K25)*E25 -> 329.98 | Q25: =F25-B25 -> 11 | R25: =IF(Q25>5,"Late","On-time") -> Late | S25: =IF(AND(Table1[[#This Row],[Status]]="Late",Table1[[#This Row],[Region]]="North"),"CRITICAL DELAY","NORMAL") -> NORMAL | T25: =OR(H25="WELCOME10",H25="FREESHIP") -> FALSE
A26: ORD-24-1010 | B26: 45311 | C26: C-003 | D26: P-505 | E26: 1 | F26: 45312 | G26: West | I26: =VLOOKUP(D26,Product_Master!$A$1:$F$8,2,FALSE) -> Dual Monitor Arm | J26: =INDEX(Product_Master!$A$1:$F$8,MATCH(Raw_orders!D26,Product_Master!$A$1:$A$8,0),3) -> Electronics | K26: =_xlfn.XLOOKUP(D26,Product_Master!A:A,Product_Master!D:D,"Not Found",0) -> 25 | L26: =_xlfn.XLOOKUP(D26,Product_Master!A:A,Product_Master!E:E,"Not Found") -> 75 | M26: =IFERROR(VLOOKUP(C26,Customer_database!$A$1:$F$11,5,FALSE),"Unknown Item") -> Emily Blunt | N26: =INDEX(Customer_database!$A$1:$F$11,MATCH(Raw_orders!C26,Customer_database!$A$1:$A$11,0),4) -> Bronze | O26: =E26*L26 -> 75 | P26: =(L26-K26)*E26 -> 50 | Q26: =F26-B26 -> 1 | R26: =IF(Q26>5,"Late","On-time") -> On-time | S26: =IF(AND(Table1[[#This Row],[Status]]="Late",Table1[[#This Row],[Region]]="North"),"CRITICAL DELAY","NORMAL") -> NORMAL | T26: =OR(H26="WELCOME10",H26="FREESHIP") -> FALSE
A27: ORD-24-1011 | B27: 45313 | C27: C-009 | D27: P-500 | E27: 20 | F27: 45314 | G27: North | H27: BULK_VIP | I27: =VLOOKUP(D27,Product_Master!$A$1:$F$8,2,FALSE) -> Wireless Mouse X1 | J27: =INDEX(Product_Master!$A$1:$F$8,MATCH(Raw_orders!D27,Product_Master!$A$1:$A$8,0),3) -> Electronics | K27: =_xlfn.XLOOKUP(D27,Product_Master!A:A,Product_Master!D:D,"Not Found",0) -> 12.5 | L27: =_xlfn.XLOOKUP(D27,Product_Master!A:A,Product_Master!E:E,"Not Found") -> 39.99 | M27: =IFERROR(VLOOKUP(C27,Customer_database!$A$1:$F$11,5,FALSE),"Unknown Item") -> Creed Bratton | N27: =INDEX(Customer_database!$A$1:$F$11,MATCH(Raw_orders!C27,Customer_database!$A$1:$A$11,0),4) -> Gold | O27: =E27*L27 -> 799.8 | P27: =(L27-K27)*E27 -> 549.8 | Q27: =F27-B27 -> 1 | R27: =IF(Q27>5,"Late","On-time") -> On-time | S27: =IF(AND(Table1[[#This Row],[Status]]="Late",Table1[[#This Row],[Region]]="North"),"CRITICAL DELAY","NORMAL") -> NORMAL | T27: =OR(H27="WELCOME10",H27="FREESHIP") -> FALSE
A28: ORD-24-1012 | B28: 45316 | C28: C-007 | D28: P-502 | E28: 3 | F28: 45327 | G28: East | I28: =VLOOKUP(D28,Product_Master!$A$1:$F$8,2,FALSE) -> Ergo Office Chair | J28: =INDEX(Product_Master!$A$1:$F$8,MATCH(Raw_orders!D28,Product_Master!$A$1:$A$8,0),3) -> Furniture | K28: =_xlfn.XLOOKUP(D28,Product_Master!A:A,Product_Master!D:D,"Not Found",0) -> 85 | L28: =_xlfn.XLOOKUP(D28,Product_Master!A:A,Product_Master!E:E,"Not Found") -> 249.99 | M28: =IFERROR(VLOOKUP(C28,Customer_database!$A$1:$F$11,5,FALSE),"Unknown Item") -> Pam Beesly | N28: =INDEX(Customer_database!$A$1:$F$11,MATCH(Raw_orders!C28,Customer_database!$A$1:$A$11,0),4) -> Silver | O28: =E28*L28 -> 749.97 | P28: =(L28-K28)*E28 -> 494.97 | Q28: =F28-B28 -> 11 | R28: =IF(Q28>5,"Late","On-time") -> Late | S28: =IF(AND(Table1[[#This Row],[Status]]="Late",Table1[[#This Row],[Region]]="North"),"CRITICAL DELAY","NORMAL") -> NORMAL | T28: =OR(H28="WELCOME10",H28="FREESHIP") -> FALSE
A29: ORD-24-1013 | B29: 45317 | C29: C-010 | D29: P-503 | E29: 2 | F29: 45319 | G29: South | H29: WELCOME10 | I29: =VLOOKUP(D29,Product_Master!$A$1:$F$8,2,FALSE) -> Oak Standing Desk | J29: =INDEX(Product_Master!$A$1:$F$8,MATCH(Raw_orders!D29,Product_Master!$A$1:$A$8,0),3) -> Furniture | K29: =_xlfn.XLOOKUP(D29,Product_Master!A:A,Product_Master!D:D,"Not Found",0) -> 160 | L29: =_xlfn.XLOOKUP(D29,Product_Master!A:A,Product_Master!E:E,"Not Found") -> 450 | M29: =IFERROR(VLOOKUP(C29,Customer_database!$A$1:$F$11,5,FALSE),"Unknown Item") -> Stanley Hudson | N29: =INDEX(Customer_database!$A$1:$F$11,MATCH(Raw_orders!C29,Customer_database!$A$1:$A$11,0),4) -> Silver | O29: =E29*L29 -> 900 | P29: =(L29-K29)*E29 -> 580 | Q29: =F29-B29 -> 2 | R29: =IF(Q29>5,"Late","On-time") -> On-time | S29: =IF(AND(Table1[[#This Row],[Status]]="Late",Table1[[#This Row],[Region]]="North"),"CRITICAL DELAY","NORMAL") -> NORMAL | T29: =OR(H29="WELCOME10",H29="FREESHIP") -> TRUE
A30: ORD-24-1014 | B30: 45319 | C30: C-005 | D30: P-504 | E30: 1 | F30: 45324 | G30: North | I30: =VLOOKUP(D30,Product_Master!$A$1:$F$8,2,FALSE) -> Smart LED Lamp | J30: =INDEX(Product_Master!$A$1:$F$8,MATCH(Raw_orders!D30,Product_Master!$A$1:$A$8,0),3) -> Home Decor | K30: =_xlfn.XLOOKUP(D30,Product_Master!A:A,Product_Master!D:D,"Not Found",0) -> 15 | L30: =_xlfn.XLOOKUP(D30,Product_Master!A:A,Product_Master!E:E,"Not Found") -> 45 | M30: =IFERROR(VLOOKUP(C30,Customer_database!$A$1:$F$11,5,FALSE),"Unknown Item") -> Dwight Schrute | N30: =INDEX(Customer_database!$A$1:$F$11,MATCH(Raw_orders!C30,Customer_database!$A$1:$A$11,0),4) -> Silver | O30: =E30*L30 -> 45 | P30: =(L30-K30)*E30 -> 30 | Q30: =F30-B30 -> 5 | R30: =IF(Q30>5,"Late","On-time") -> On-time | S30: =IF(AND(Table1[[#This Row],[Status]]="Late",Table1[[#This Row],[Region]]="North"),"CRITICAL DELAY","NORMAL") -> NORMAL | T30: =OR(H30="WELCOME10",H30="FREESHIP") -> FALSE
A31: ORD-24-1015 | B31: 45321 | C31: C-001 | D31: P-501 | E31: 5 | F31: 45323 | G31: North | H31: FREESHIP | I31: =VLOOKUP(D31,Product_Master!$A$1:$F$8,2,FALSE) -> Mech Keyboard RGB | J31: =INDEX(Product_Master!$A$1:$F$8,MATCH(Raw_orders!D31,Product_Master!$A$1:$A$8,0),3) -> Electronics | K31: =_xlfn.XLOOKUP(D31,Product_Master!A:A,Product_Master!D:D,"Not Found",0) -> 45 | L31: =_xlfn.XLOOKUP(D31,Product_Master!A:A,Product_Master!E:E,"Not Found") -> 129.99 | M31: =IFERROR(VLOOKUP(C31,Customer_database!$A$1:$F$11,5,FALSE),"Unknown Item") -> John Smith | N31: =INDEX(Customer_database!$A$1:$F$11,MATCH(Raw_orders!C31,Customer_database!$A$1:$A$11,0),4) -> Gold | O31: =E31*L31 -> 649.95 | P31: =(L31-K31)*E31 -> 424.95 | Q31: =F31-B31 -> 2 | R31: =IF(Q31>5,"Late","On-time") -> On-time | S31: =IF(AND(Table1[[#This Row],[Status]]="Late",Table1[[#This Row],[Region]]="North"),"CRITICAL DELAY","NORMAL") -> NORMAL | T31: =OR(H31="WELCOME10",H31="FREESHIP") -> TRUE
A32: ORD-24-1001 | B32: 45294 | C32: C-001 | D32: P-500 | E32: 5 | F32: 45301 | G32: North | H32: WELCOME10 | I32: =VLOOKUP(D32,Product_Master!$A$1:$F$8,2,FALSE) -> Wireless Mouse X1 | J32: =INDEX(Product_Master!$A$1:$F$8,MATCH(Raw_orders!D32,Product_Master!$A$1:$A$8,0),3) -> Electronics | K32: =_xlfn.XLOOKUP(D32,Product_Master!A:A,Product_Master!D:D,"Not Found",0) -> 12.5 | L32: =_xlfn.XLOOKUP(D32,Product_Master!A:A,Product_Master!E:E,"Not Found") -> 39.99 | M32: =IFERROR(VLOOKUP(C32,Customer_database!$A$1:$F$11,5,FALSE),"Unknown Item") -> John Smith | N32: =INDEX(Customer_database!$A$1:$F$11,MATCH(Raw_orders!C32,Customer_database!$A$1:$A$11,0),4) -> Gold | O32: =E32*L32 -> 199.95 | P32: =(L32-K32)*E32 -> 137.45 | Q32: =F32-B32 -> 7 | R32: =IF(Q32>5,"Late","On-time") -> Late | S32: =IF(AND(Table1[[#This Row],[Status]]="Late",Table1[[#This Row],[Region]]="North"),"CRITICAL DELAY","NORMAL") -> CRITICAL DELAY | T32: =OR(H32="WELCOME10",H32="FREESHIP") -> TRUE
A33: ORD-24-1002 | B33: 45295 | C33: C-003 | D33: P-502 | E33: 1 | F33: 45299 | G33: West | I33: =VLOOKUP(D33,Product_Master!$A$1:$F$8,2,FALSE) -> Ergo Office Chair | J33: =INDEX(Product_Master!$A$1:$F$8,MATCH(Raw_orders!D33,Product_Master!$A$1:$A$8,0),3) -> Furniture | K33: =_xlfn.XLOOKUP(D33,Product_Master!A:A,Product_Master!D:D,"Not Found",0) -> 85 | L33: =_xlfn.XLOOKUP(D33,Product_Master!A:A,Product_Master!E:E,"Not Found") -> 249.99 | M33: =IFERROR(VLOOKUP(C33,Customer_database!$A$1:$F$11,5,FALSE),"Unknown Item") -> Emily Blunt | N33: =INDEX(Customer_database!$A$1:$F$11,MATCH(Raw_orders!C33,Customer_database!$A$1:$A$11,0),4) -> Bronze | O33: =E33*L33 -> 249.99 | P33: =(L33-K33)*E33 -> 164.99 | Q33: =F33-B33 -> 4 | R33: =IF(Q33>5,"Late","On-time") -> On-time | S33: =IF(AND(Table1[[#This Row],[Status]]="Late",Table1[[#This Row],[Region]]="North"),"CRITICAL DELAY","NORMAL") -> NORMAL | T33: =OR(H33="WELCOME10",H33="FREESHIP") -> FALSE
A34: ORD-24-1003 | B34: 45297 | C34: C-002 | D34: P-501 | E34: 10 | F34: 45305 | G34: East | H34: BULK25 | I34: =VLOOKUP(D34,Product_Master!$A$1:$F$8,2,FALSE) -> Mech Keyboard RGB | J34: =INDEX(Product_Master!$A$1:$F$8,MATCH(Raw_orders!D34,Product_Master!$A$1:$A$8,0),3) -> Electronics | K34: =_xlfn.XLOOKUP(D34,Product_Master!A:A,Product_Master!D:D,"Not Found",0) -> 45 | L34: =_xlfn.XLOOKUP(D34,Product_Master!A:A,Product_Master!E:E,"Not Found") -> 129.99 | M34: =IFERROR(VLOOKUP(C34,Customer_database!$A$1:$F$11,5,FALSE),"Unknown Item") -> Sarah Connor | N34: =INDEX(Customer_database!$A$1:$F$11,MATCH(Raw_orders!C34,Customer_database!$A$1:$A$11,0),4) -> Silver | O34: =E34*L34 -> 1299.9 | P34: =(L34-K34)*E34 -> 849.9 | Q34: =F34-B34 -> 8 | R34: =IF(Q34>5,"Late","On-time") -> Late | S34: =IF(AND(Table1[[#This Row],[Status]]="Late",Table1[[#This Row],[Region]]="North"),"CRITICAL DELAY","NORMAL") -> NORMAL | T34: =OR(H34="WELCOME10",H34="FREESHIP") -> FALSE
A35: ORD-24-1004 | B35: 45299 | C35: C-005 | D35: P-505 | E35: 2 | F35: 45300 | G35: North | I35: =VLOOKUP(D35,Product_Master!$A$1:$F$8,2,FALSE) -> Dual Monitor Arm | J35: =INDEX(Product_Master!$A$1:$F$8,MATCH(Raw_orders!D35,Product_Master!$A$1:$A$8,0),3) -> Electronics | K35: =_xlfn.XLOOKUP(D35,Product_Master!A:A,Product_Master!D:D,"Not Found",0) -> 25 | L35: =_xlfn.XLOOKUP(D35,Product_Master!A:A,Product_Master!E:E,"Not Found") -> 75 | M35: =IFERROR(VLOOKUP(C35,Customer_database!$A$1:$F$11,5,FALSE),"Unknown Item") -> Dwight Schrute | N35: =INDEX(Customer_database!$A$1:$F$11,MATCH(Raw_orders!C35,Customer_database!$A$1:$A$11,0),4) -> Silver | O35: =E35*L35 -> 150 | P35: =(L35-K35)*E35 -> 100 | Q35: =F35-B35 -> 1 | R35: =IF(Q35>5,"Late","On-time") -> On-time | S35: =IF(AND(Table1[[#This Row],[Status]]="Late",Table1[[#This Row],[Region]]="North"),"CRITICAL DELAY","NORMAL") -> NORMAL | T35: =OR(H35="WELCOME10",H35="FREESHIP") -> FALSE
A36: ORD-24-1005 | B36: 45301 | C36: C-001 | D36: P-500 | E36: 1 | F36: 45303 | G36: North | H36: FREESHIP | I36: =VLOOKUP(D36,Product_Master!$A$1:$F$8,2,FALSE) -> Wireless Mouse X1 | J36: =INDEX(Product_Master!$A$1:$F$8,MATCH(Raw_orders!D36,Product_Master!$A$1:$A$8,0),3) -> Electronics | K36: =_xlfn.XLOOKUP(D36,Product_Master!A:A,Product_Master!D:D,"Not Found",0) -> 12.5 | L36: =_xlfn.XLOOKUP(D36,Product_Master!A:A,Product_Master!E:E,"Not Found") -> 39.99 | M36: =IFERROR(VLOOKUP(C36,Customer_database!$A$1:$F$11,5,FALSE),"Unknown Item") -> John Smith | N36: =INDEX(Customer_database!$A$1:$F$11,MATCH(Raw_orders!C36,Customer_database!$A$1:$A$11,0),4) -> Gold | O36: =E36*L36 -> 39.99 | P36: =(L36-K36)*E36 -> 27.49 | Q36: =F36-B36 -> 2 | R36: =IF(Q36>5,"Late","On-time") -> On-time | S36: =IF(AND(Table1[[#This Row],[Status]]="Late",Table1[[#This Row],[Region]]="North"),"CRITICAL DELAY","NORMAL") -> NORMAL | T36: =OR(H36="WELCOME10",H36="FREESHIP") -> TRUE
A37: ORD-24-1006 | B37: 45303 | C37: C-004 | D37: P-503 | E37: 3 | F37: 45310 | G37: South | H37: WELCOME10 | I37: =VLOOKUP(D37,Product_Master!$A$1:$F$8,2,FALSE) -> Oak Standing Desk | J37: =INDEX(Product_Master!$A$1:$F$8,MATCH(Raw_orders!D37,Product_Master!$A$1:$A$8,0),3) -> Furniture | K37: =_xlfn.XLOOKUP(D37,Product_Master!A:A,Product_Master!D:D,"Not Found",0) -> 160 | L37: =_xlfn.XLOOKUP(D37,Product_Master!A:A,Product_Master!E:E,"Not Found") -> 450 | M37: =IFERROR(VLOOKUP(C37,Customer_database!$A$1:$F$11,5,FALSE),"Unknown Item") -> Michael Scott | N37: =INDEX(Customer_database!$A$1:$F$11,MATCH(Raw_orders!C37,Customer_database!$A$1:$A$11,0),4) -> Gold | O37: =E37*L37 -> 1350 | P37: =(L37-K37)*E37 -> 870 | Q37: =F37-B37 -> 7 | R37: =IF(Q37>5,"Late","On-time") -> Late | S37: =IF(AND(Table1[[#This Row],[Status]]="Late",Table1[[#This Row],[Region]]="North"),"CRITICAL DELAY","NORMAL") -> NORMAL | T37: =OR(H37="WELCOME10",H37="FREESHIP") -> TRUE
A38: ORD-24-1007 | B38: 45306 | C38: C-006 | D38: P-504 | E38: 4 | F38: 45313 | G38: West | I38: =VLOOKUP(D38,Product_Master!$A$1:$F$8,2,FALSE) -> Smart LED Lamp | J38: =INDEX(Product_Master!$A$1:$F$8,MATCH(Raw_orders!D38,Product_Master!$A$1:$A$8,0),3) -> Home Decor | K38: =_xlfn.XLOOKUP(D38,Product_Master!A:A,Product_Master!D:D,"Not Found",0) -> 15 | L38: =_xlfn.XLOOKUP(D38,Product_Master!A:A,Product_Master!E:E,"Not Found") -> 45 | M38: =IFERROR(VLOOKUP(C38,Customer_database!$A$1:$F$11,5,FALSE),"Unknown Item") -> Jim Halpert | N38: =INDEX(Customer_database!$A$1:$F$11,MATCH(Raw_orders!C38,Customer_database!$A$1:$A$11,0),4) -> Bronze | O38: =E38*L38 -> 180 | P38: =(L38-K38)*E38 -> 120 | Q38: =F38-B38 -> 7 | R38: =IF(Q38>5,"Late","On-time") -> Late | S38: =IF(AND(Table1[[#This Row],[Status]]="Late",Table1[[#This Row],[Region]]="North"),"CRITICAL DELAY","NORMAL") -> NORMAL | T38: =OR(H38="WELCOME10",H38="FREESHIP") -> FALSE
A39: ORD-24-1008 | B39: 45307 | C39: C-002 | D39: P-501 | E39: 6 | F39: 45309 | G39: East | I39: =VLOOKUP(D39,Product_Master!$A$1:$F$8,2,FALSE) -> Mech Keyboard RGB | J39: =INDEX(Product_Master!$A$1:$F$8,MATCH(Raw_orders!D39,Product_Master!$A$1:$A$8,0),3) -> Electronics | K39: =_xlfn.XLOOKUP(D39,Product_Master!A:A,Product_Master!D:D,"Not Found",0) -> 45 | L39: =_xlfn.XLOOKUP(D39,Product_Master!A:A,Product_Master!E:E,"Not Found") -> 129.99 | M39: =IFERROR(VLOOKUP(C39,Customer_database!$A$1:$F$11,5,FALSE),"Unknown Item") -> Sarah Connor | N39: =INDEX(Customer_database!$A$1:$F$11,MATCH(Raw_orders!C39,Customer_database!$A$1:$A$11,0),4) -> Silver | O39: =E39*L39 -> 779.94 | P39: =(L39-K39)*E39 -> 509.94 | Q39: =F39-B39 -> 2 | R39: =IF(Q39>5,"Late","On-time") -> On-time | S39: =IF(AND(Table1[[#This Row],[Status]]="Late",Table1[[#This Row],[Region]]="North"),"CRITICAL DELAY","NORMAL") -> NORMAL | T39: =OR(H39="WELCOME10",H39="FREESHIP") -> FALSE
A40: ORD-24-1009 | B40: 45309 | C40: C-008 | D40: P-502 | E40: 2 | F40: 45320 | G40: South | H40: LATE_SORRY | I40: =VLOOKUP(D40,Product_Master!$A$1:$F$8,2,FALSE) -> Ergo Office Chair | J40: =INDEX(Product_Master!$A$1:$F$8,MATCH(Raw_orders!D40,Product_Master!$A$1:$A$8,0),3) -> Furniture | K40: =_xlfn.XLOOKUP(D40,Product_Master!A:A,Product_Master!D:D,"Not Found",0) -> 85 | L40: =_xlfn.XLOOKUP(D40,Product_Master!A:A,Product_Master!E:E,"Not Found") -> 249.99 | M40: =IFERROR(VLOOKUP(C40,Customer_database!$A$1:$F$11,5,FALSE),"Unknown Item") -> Ryan Howard | N40: =INDEX(Customer_database!$A$1:$F$11,MATCH(Raw_orders!C40,Customer_database!$A$1:$A$11,0),4) -> Bronze | O40: =E40*L40 -> 499.98 | P40: =(L40-K40)*E40 -> 329.98 | Q40: =F40-B40 -> 11 | R40: =IF(Q40>5,"Late","On-time") -> Late | S40: =IF(AND(Table1[[#This Row],[Status]]="Late",Table1[[#This Row],[Region]]="North"),"CRITICAL DELAY","NORMAL") -> NORMAL | T40: =OR(H40="WELCOME10",H40="FREESHIP") -> FALSE
...

Sheet Product_Master
A1: Prod_ID | B1: Product_Name | C1: Category | D1: Unit_Cost | E1: Unit_Price | F1: Supplier
A2: P-500 | B2: Wireless Mouse X1 | C2: Electronics | D2: 12.5 | E2: 39.99 | F2: TechGiant
A3: P-501 | B3: Mech Keyboard RGB | C3: Electronics | D3: 45 | E3: 129.99 | F3: KeyWorld
A4: P-502 | B4: Ergo Office Chair | C4: Furniture | D4: 85 | E4: 249.99 | F4: SitRight
A5: P-503 | B5: Oak Standing Desk | C5: Furniture | D5: 160 | E5: 450 | F5: WoodWorks
A6: P-504 | B6: Smart LED Lamp | C6: Home Decor | D6: 15 | E6: 45 | F6: BrightLite
A7: P-505 | B7: Dual Monitor Arm | C7: Electronics | D7: 25 | E7: 75 | F7: TechGiant
A8: P-999 | B8: Extended Warranty | C8: Services | D8: 5 | E8: 25 | F8: ApexLogistics

Sheet Customer_database
A1: Cust_ID | B1: Customer_Raw_Name | C1: Email_Address | D1: Membership_Tier | E1: Clean_name | F1: Domain_name
A2: C-001 | B2: john smith | C2: j.smith@gmail.com | D2: Gold | E2: =TRIM(PROPER(B2)) -> John Smith | F2: gmail.com
A3: C-002 | B3: SARAH CONNOR | C3: s.connor@skynet.org | D3: Silver | E3: =TRIM(PROPER(B3)) -> Sarah Connor | F3: skynet.org
A4: C-003 | B4: emily blunt | C4: e.blunt@studio.net | D4: Bronze | E4: =TRIM(PROPER(B4)) -> Emily Blunt | F4: studio.net
A5: C-004 | B5: MICHAEL scott | C5: m.scott@paperco.com | D5: Gold | E5: =TRIM(PROPER(B5)) -> Michael Scott | F5: paperco.com
A6: C-005 | B6: dwight Schrute | C6: beets@farms.com | D6: Silver | E6: =TRIM(PROPER(B6)) -> Dwight Schrute | F6: farms.com
A7: C-006 | B7: jim HALPERT | C7: jim@paperco.com | D7: Bronze | E7: =TRIM(PROPER(B7)) -> Jim Halpert | F7: paperco.com
A8: C-007 | B8: pam beesly | C8: art@paperco.com | D8: Silver | E8: =TRIM(PROPER(B8)) -> Pam Beesly | F8: paperco.com
A9: C-008 | B9: ryan howard | C9: temp@agency.com | D9: Bronze | E9: =TRIM(PROPER(B9)) -> Ryan Howard | F9: agency.com
A10: C-009 | B10: Creed Bratton | C10: unknown@unknown.com | D10: Gold | E10: =TRIM(PROPER(B10)) -> Creed Bratton | F10: unknown.com
A11: C-010 | B11: stanley hudson | C11: crossword@paperco.com | D11: Silver | E11: =TRIM(PROPER(B11)) -> Stanley Hudson | F11: paperco.com

Sheet Report
A1: Row Labels | B1: Sum of Total_Revenue | F1: Row Labels | G1: Count of Remark | J1: Row Labels | K1: Sum of Total_Revenue
A2: Dual Monitor Arm | B2: 675 | F2: East | G2: 9 | J2: Bronze | K2: 3014.91
A3: Ergo Office Chair | B3: 4499.82 | F3: NORMAL | G3: 9 | J3: Gold | K3: 9119.07
A4: Mech Keyboard RGB | B4: 8189.37 | F4: North | G4: 18 | J4: Silver | K4: 11774.43
A5: Oak Standing Desk | B5: 6750 | F5: CRITICAL DELAY | G5: 1 | J5: Grand Total | K5: 23908.41
A6: Smart LED Lamp | B6: 675 | F6: NORMAL | G6: 17
A7: Wireless Mouse X1 | B7: 3119.22 | F7: South | G7: 9
A8: Grand Total | B8: 23908.41 | F8: NORMAL | G8: 9
F9: West | G9: 9 | J9: Row Labels | K9: Sum of Total_Revenue
F10: NORMAL | G10: 9 | J10: Electronics | K10: 11983.59
F11: Grand Total | G11: 45 | J11: Furniture | K11: 11249.82
J12: Home Decor | K12: 675
J13: Grand Total | K13: 23908.41
B14: Row Labels | C14: Count of OrderID
B15: Late | C15: 16
B16: On-time | C16: 29
B17: Grand Total | C17: 45

Sheet Visualization
