Workbook
Name NativeTimeline_Date: #N/A
Name Slicer_Category: #N/A

Sheet Raw_orders
A1: OrderID | B1: Date | C1: Cust_ID | D1: Prod_ID | E1: Qty | F1: Ship_Date | G1: Region | H1: Promo_Code | I1: Product name | J1: Category | K1: Unit Cost | L1: Unit Price | M1: Clear Name | N1: Membership_Tier | O1: Total Revenew | P1: Total Profit | Q1: Days_To_Ship | R1: Status | S1: Promo Valid
A2: ORD-24-1001 | B2: 45294 | C2: C-001 | D2: P-500 | E2: 5 | F2: 45296 | G2: North | H2: WELCOME10 | I2: =VLOOKUP(D2,Product_Master!$A$1:$F$8,2,FALSE) -> Wireless Mouse X1 | J2: =VLOOKUP(D2,Product_Master!$A$1:$F$8,3,FALSE) -> Electronics | K2: =VLOOKUP(D2:D46,Product_Master!$A$1:$F$8,4,FALSE) -> 12.5 | L2: =VLOOKUP(D2:D46,Product_Master!$A$1:$F$8,5,FALSE) -> 39.99 | M2: =IFERROR(VLOOKUP(C2:C46,Customer_database!$A$1:$F$11,5,FALSE),"Unknown Item") -> John Smith | N2: =IFERROR(VLOOKUP(C2:C46,Customer_database!$A$1:$F$11,4,FALSE),"Unknown Item") -> Gold | O2: =(E2*K2) -> 62.5 | P2: =((L2-K2)*E2) -> 137.45 | Q2: =(F2-B2) -> 2 | R2: =IF(AND(Q2>5,G2="North"),"CRITICAL DELAY",IF(Q2>5,"Late","On Time")) -> On Time | S2: =OR(H2="WELCOME10",H2="FREESHIP") -> TRUE
A3: ORD-24-1002 | B3: 45295 | C3: C-003 | D3: P-502 | E3: 1 | F3: 45299 | G3: West | I3: =VLOOKUP(D3,Product_Master!$A$1:$F$8,2,FALSE) -> Ergo Office Chair | J3: =VLOOKUP(D3,Product_Master!$A$1:$F$8,3,FALSE) -> Furniture | K3: =VLOOKUP(D3:D47,Product_Master!$A$1:$F$8,4,FALSE) -> 85 | L3: =VLOOKUP(D3:D47,Product_Master!$A$1:$F$8,5,FALSE) -> 249.99 | M3: =IFERROR(VLOOKUP(C3:C47,Customer_database!$A$1:$F$11,5,FALSE),"Unknown Item") -> Emily Blunt | N3: =IFERROR(VLOOKUP(C3:C47,Customer_database!$A$1:$F$11,4,FALSE),"Unknown Item") -> Bronze | O3: =(E3*K3) -> 85 | P3: =((L3-K3)*E3) -> 164.99 | Q3: =(F3-B3) -> 4 | R3: =IF(AND(Q3>5,G3="North"),"CRITICAL DELAY",IF(Q3>5,"Late","On Time")) -> On Time | S3: =OR(H3="WELCOME10",H3="FREESHIP") -> FALSE
A4: ORD-24-1003 | B4: 45297 | C4: C-002 | D4: P-501 | E4: 10 | F4: 45305 | G4: East | H4: BULK25 | I4: =VLOOKUP(D4,Product_Master!$A$1:$F$8,2,FALSE) -> Mech Keyboard RGB | J4: =VLOOKUP(D4,Product_Master!$A$1:$F$8,3,FALSE) -> Electronics | K4: =VLOOKUP(D4:D48,Product_Master!$A$1:$F$8,4,FALSE) -> 45 | L4: =VLOOKUP(D4:D48,Product_Master!$A$1:$F$8,5,FALSE) -> 129.99 | M4: =IFERROR(VLOOKUP(C4:C48,Customer_database!$A$1:$F$11,5,FALSE),"Unknown Item") -> Sarah Connor | N4: =IFERROR(VLOOKUP(C4:C48,Customer_database!$A$1:$F$11,4,FALSE),"Unknown Item") -> Silver | O4: =(E4*K4) -> 450 | P4: =((L4-K4)*E4) -> 849.9 | Q4: =(F4-B4) -> 8 | R4: =IF(AND(Q4>5,G4="North"),"CRITICAL DELAY",IF(Q4>5,"Late","On Time")) -> Late | S4: =OR(H4="WELCOME10",H4="FREESHIP") -> FALSE
A5: ORD-24-1004 | B5: 45299 | C5: C-005 | D5: P-505 | E5: 2 | F5: 45300 | G5: North | I5: =VLOOKUP(D5,Product_Master!$A$1:$F$8,2,FALSE) -> Dual Monitor Arm | J5: =VLOOKUP(D5,Product_Master!$A$1:$F$8,3,FALSE) -> Electronics | K5: =VLOOKUP(D5:D49,Product_Master!$A$1:$F$8,4,FALSE) -> 25 | L5: =VLOOKUP(D5:D49,Product_Master!$A$1:$F$8,5,FALSE) -> 75 | M5: =IFERROR(VLOOKUP(C5:C49,Customer_database!$A$1:$F$11,5,FALSE),"Unknown Item") -> Dwight Schrute | N5: =IFERROR(VLOOKUP(C5:C49,Customer_database!$A$1:$F$11,4,FALSE),"Unknown Item") -> Silver | O5: =(E5*K5) -> 50 | P5: =((L5-K5)*E5) -> 100 | Q5: =(F5-B5) -> 1 | R5: =IF(AND(Q5>5,G5="North"),"CRITICAL DELAY",IF(Q5>5,"Late","On Time")) -> On Time | S5: =OR(H5="WELCOME10",H5="FREESHIP") -> FALSE
A6: ORD-24-1005 | B6: 45301 | C6: C-001 | D6: P-500 | E6: 1 | F6: 45303 | G6: North | H6: FREESHIP | I6: =VLOOKUP(D6,Product_Master!$A$1:$F$8,2,FALSE) -> Wireless Mouse X1 | J6: =VLOOKUP(D6,Product_Master!$A$1:$F$8,3,FALSE) -> Electronics | K6: =VLOOKUP(D6:D50,Product_Master!$A$1:$F$8,4,FALSE) -> 12.5 | L6: =VLOOKUP(D6:D50,Product_Master!$A$1:$F$8,5,FALSE) -> 39.99 | M6: =IFERROR(VLOOKUP(C6:C50,Customer_database!$A$1:$F$11,5,FALSE),"Unknown Item") -> John Smith | N6: =IFERROR(VLOOKUP(C6:C50,Customer_database!$A$1:$F$11,4,FALSE),"Unknown Item") -> Gold | O6: =(E6*K6) -> 12.5 | P6: =((L6-K6)*E6) -> 27.49 | Q6: =(F6-B6) -> 2 | R6: =IF(AND(Q6>5,G6="North"),"CRITICAL DELAY",IF(Q6>5,"Late","On Time")) -> On Time | S6: =OR(H6="WELCOME10",H6="FREESHIP") -> TRUE
A7: ORD-24-1006 | B7: 45303 | C7: C-004 | D7: P-503 | E7: 3 | F7: 45310 | G7: South | H7: WELCOME10 | I7: =VLOOKUP(D7,Product_Master!$A$1:$F$8,2,FALSE) -> Oak Standing Desk | J7: =VLOOKUP(D7,Product_Master!$A$1:$F$8,3,FALSE) -> Furniture | K7: =VLOOKUP(D7:D51,Product_Master!$A$1:$F$8,4,FALSE) -> 160 | L7: =VLOOKUP(D7:D51,Product_Master!$A$1:$F$8,5,FALSE) -> 450 | M7: =IFERROR(VLOOKUP(C7:C51,Customer_database!$A$1:$F$11,5,FALSE),"Unknown Item") -> Michael Scott | N7: =IFERROR(VLOOKUP(C7:C51,Customer_database!$A$1:$F$11,4,FALSE),"Unknown Item") -> Gold | O7: =(E7*K7) -> 480 | P7: =((L7-K7)*E7) -> 870 | Q7: =(F7-B7) -> 7 | R7: =IF(AND(Q7>5,G7="North"),"CRITICAL DELAY",IF(Q7>5,"Late","On Time")) -> Late | S7: =OR(H7="WELCOME10",H7="FREESHIP") -> TRUE
A8: ORD-24-1007 | B8: 45306 | C8: C-006 | D8: P-504 | E8: 4 | F8: 45313 | G8: West | I8: =VLOOKUP(D8,Product_Master!$A$1:$F$8,2,FALSE) -> Smart LED Lamp | J8: =VLOOKUP(D8,Product_Master!$A$1:$F$8,3,FALSE) -> Home Decor | K8: =VLOOKUP(D8:D52,Product_Master!$A$1:$F$8,4,FALSE) -> 15 | L8: =VLOOKUP(D8:D52,Product_Master!$A$1:$F$8,5,FALSE) -> 45 | M8: =IFERROR(VLOOKUP(C8:C52,Customer_database!$A$1:$F$11,5,FALSE),"Unknown Item") -> Jim Halpert | N8: =IFERROR(VLOOKUP(C8:C52,Customer_database!$A$1:$F$11,4,FALSE),"Unknown Item") -> Bronze | O8: =(E8*K8) -> 60 | P8: =((L8-K8)*E8) -> 120 | Q8: =(F8-B8) -> 7 | R8: =IF(AND(Q8>5,G8="North"),"CRITICAL DELAY",IF(Q8>5,"Late","On Time")) -> Late | S8: =OR(H8="WELCOME10",H8="FREESHIP") -> FALSE
A9: ORD-24-1008 | B9: 45307 | C9: C-002 | D9: P-501 | E9: 6 | F9: 45309 | G9: East | I9: =VLOOKUP(D9,Product_Master!$A$1:$F$8,2,FALSE) -> Mech Keyboard RGB | J9: =VLOOKUP(D9,Product_Master!$A$1:$F$8,3,FALSE) -> Electronics | K9: =VLOOKUP(D9:D53,Product_Master!$A$1:$F$8,4,FALSE) -> 45 | L9: =VLOOKUP(D9:D53,Product_Master!$A$1:$F$8,5,FALSE) -> 129.99 | M9: =IFERROR(VLOOKUP(C9:C53,Customer_database!$A$1:$F$11,5,FALSE),"Unknown Item") -> Sarah Connor | N9: =IFERROR(VLOOKUP(C9:C53,Customer_database!$A$1:$F$11,4,FALSE),"Unknown Item") -> Silver | O9: =(E9*K9) -> 270 | P9: =((L9-K9)*E9) -> 509.94 | Q9: =(F9-B9) -> 2 | R9: =IF(AND(Q9>5,G9="North"),"CRITICAL DELAY",IF(Q9>5,"Late","On Time")) -> On Time | S9: =OR(H9="WELCOME10",H9="FREESHIP") -> FALSE
A10: ORD-24-1009 | B10: 45309 | C10: C-008 | D10: P-502 | E10: 2 | F10: 45320 | G10: South | H10: LATE_SORRY | I10: =VLOOKUP(D10,Product_Master!$A$1:$F$8,2,FALSE) -> Ergo Office Chair | J10: =VLOOKUP(D10,Product_Master!$A$1:$F$8,3,FALSE) -> Furniture | K10: =VLOOKUP(D10:D54,Product_Master!$A$1:$F$8,4,FALSE) -> 85 | L10: =VLOOKUP(D10:D54,Product_Master!$A$1:$F$8,5,FALSE) -> 249.99 | M10: =IFERROR(VLOOKUP(C10:C54,Customer_database!$A$1:$F$11,5,FALSE),"Unknown Item") -> Ryan Howard | N10: =IFERROR(VLOOKUP(C10:C54,Customer_database!$A$1:$F$11,4,FALSE),"Unknown Item") -> Bronze | O10: =(E10*K10) -> 170 | P10: =((L10-K10)*E10) -> 329.98 | Q10: =(F10-B10) -> 11 | R10: =IF(AND(Q10>5,G10="North"),"CRITICAL DELAY",IF(Q10>5,"Late","On Time")) -> Late | S10: =OR(H10="WELCOME10",H10="FREESHIP") -> FALSE
A11: ORD-24-1010 | B11: 45311 | C11: C-003 | D11: P-505 | E11: 1 | F11: 45312 | G11: West | I11: =VLOOKUP(D11,Product_Master!$A$1:$F$8,2,FALSE) -> Dual Monitor Arm | J11: =VLOOKUP(D11,Product_Master!$A$1:$F$8,3,FALSE) -> Electronics | K11: =VLOOKUP(D11:D55,Product_Master!$A$1:$F$8,4,FALSE) -> 25 | L11: =VLOOKUP(D11:D55,Product_Master!$A$1:$F$8,5,FALSE) -> 75 | M11: =IFERROR(VLOOKUP(C11:C55,Customer_database!$A$1:$F$11,5,FALSE),"Unknown Item") -> Emily Blunt | N11: =IFERROR(VLOOKUP(C11:C55,Customer_database!$A$1:$F$11,4,FALSE),"Unknown Item") -> Bronze | O11: =(E11*K11) -> 25 | P11: =((L11-K11)*E11) -> 50 | Q11: =(F11-B11) -> 1 | R11: =IF(AND(Q11>5,G11="North"),"CRITICAL DELAY",IF(Q11>5,"Late","On Time")) -> On Time | S11: =OR(H11="WELCOME10",H11="FREESHIP") -> FALSE
A12: ORD-24-1011 | B12: 45313 | C12: C-009 | D12: P-500 | E12: 20 | F12: 45314 | G12: North | H12: BULK_VIP | I12: =VLOOKUP(D12,Product_Master!$A$1:$F$8,2,FALSE) -> Wireless Mouse X1 | J12: =VLOOKUP(D12,Product_Master!$A$1:$F$8,3,FALSE) -> Electronics | K12: =VLOOKUP(D12:D56,Product_Master!$A$1:$F$8,4,FALSE) -> 12.5 | L12: =VLOOKUP(D12:D56,Product_Master!$A$1:$F$8,5,FALSE) -> 39.99 | M12: =IFERROR(VLOOKUP(C12:C56,Customer_database!$A$1:$F$11,5,FALSE),"Unknown Item") -> Creed Bratton | N12: =IFERROR(VLOOKUP(C12:C56,Customer_database!$A$1:$F$11,4,FALSE),"Unknown Item") -> Gold | O12: =(E12*K12) -> 250 | P12: =((L12-K12)*E12) -> 549.8 | Q12: =(F12-B12) -> 1 | R12: =IF(AND(Q12>5,G12="North"),"CRITICAL DELAY",IF(Q12>5,"Late","On Time")) -> On Time | S12: =OR(H12="WELCOME10",H12="FREESHIP") -> FALSE
A13: ORD-24-1012 | B13: 45316 | C13: C-007 | D13: P-502 | E13: 3 | F13: 45327 | G13: East | I13: =VLOOKUP(D13,Product_Master!$A$1:$F$8,2,FALSE) -> Ergo Office Chair | J13: =VLOOKUP(D13,Product_Master!$A$1:$F$8,3,FALSE) -> Furniture | K13: =VLOOKUP(D13:D57,Product_Master!$A$1:$F$8,4,FALSE) -> 85 | L13: =VLOOKUP(D13:D57,Product_Master!$A$1:$F$8,5,FALSE) -> 249.99 | M13: =IFERROR(VLOOKUP(C13:C57,Customer_database!$A$1:$F$11,5,FALSE),"Unknown Item") -> Pam Beesly | N13: =IFERROR(VLOOKUP(C13:C57,Customer_database!$A$1:$F$11,4,FALSE),"Unknown Item") -> Silver | O13: =(E13*K13) -> 255 | P13: =((L13-K13)*E13) -> 494.97 | Q13: =(F13-B13) -> 11 | R13: =IF(AND(Q13>5,G13="North"),"CRITICAL DELAY",IF(Q13>5,"Late","On Time")) -> Late | S13: =OR(H13="WELCOME10",H13="FREESHIP") -> FALSE
A14: ORD-24-1013 | B14: 45317 | C14: C-010 | D14: P-503 | E14: 2 | F14: 45319 | G14: South | H14: WELCOME10 | I14: =VLOOKUP(D14,Product_Master!$A$1:$F$8,2,FALSE) -> Oak Standing Desk | J14: =VLOOKUP(D14,Product_Master!$A$1:$F$8,3,FALSE) -> Furniture | K14: =VLOOKUP(D14:D58,Product_Master!$A$1:$F$8,4,FALSE) -> 160 | L14: =VLOOKUP(D14:D58,Product_Master!$A$1:$F$8,5,FALSE) -> 450 | M14: =IFERROR(VLOOKUP(C14:C58,Customer_database!$A$1:$F$11,5,FALSE),"Unknown Item") -> Stanley Hudson | N14: =IFERROR(VLOOKUP(C14:C58,Customer_database!$A$1:$F$11,4,FALSE),"Unknown Item") -> Silver | O14: =(E14*K14) -> 320 | P14: =((L14-K14)*E14) -> 580 | Q14: =(F14-B14) -> 2 | R14: =IF(AND(Q14>5,G14="North"),"CRITICAL DELAY",IF(Q14>5,"Late","On Time")) -> On Time | S14: =OR(H14="WELCOME10",H14="FREESHIP") -> TRUE
A15: ORD-24-1014 | B15: 45319 | C15: C-005 | D15: P-504 | E15: 1 | F15: 45324 | G15: North | I15: =VLOOKUP(D15,Product_Master!$A$1:$F$8,2,FALSE) -> Smart LED Lamp | J15: =VLOOKUP(D15,Product_Master!$A$1:$F$8,3,FALSE) -> Home Decor | K15: =VLOOKUP(D15:D59,Product_Master!$A$1:$F$8,4,FALSE) -> 15 | L15: =VLOOKUP(D15:D59,Product_Master!$A$1:$F$8,5,FALSE) -> 45 | M15: =IFERROR(VLOOKUP(C15:C59,Customer_database!$A$1:$F$11,5,FALSE),"Unknown Item") -> Dwight Schrute | N15: =IFERROR(VLOOKUP(C15:C59,Customer_database!$A$1:$F$11,4,FALSE),"Unknown Item") -> Silver | O15: =(E15*K15) -> 15 | P15: =((L15-K15)*E15) -> 30 | Q15: =(F15-B15) -> 5 | R15: =IF(AND(Q15>5,G15="North"),"CRITICAL DELAY",IF(Q15>5,"Late","On Time")) -> On Time | S15: =OR(H15="WELCOME10",H15="FREESHIP") -> FALSE
A16: ORD-24-1015 | B16: 45321 | C16: C-001 | D16: P-501 | E16: 5 | F16: 45323 | G16: North | H16: FREESHIP | I16: =VLOOKUP(D16,Product_Master!$A$1:$F$8,2,FALSE) -> Mech Keyboard RGB | J16: =VLOOKUP(D16,Product_Master!$A$1:$F$8,3,FALSE) -> Electronics | K16: =VLOOKUP(D16:D60,Product_Master!$A$1:$F$8,4,FALSE) -> 45 | L16: =VLOOKUP(D16:D60,Product_Master!$A$1:$F$8,5,FALSE) -> 129.99 | M16: =IFERROR(VLOOKUP(C16:C60,Customer_database!$A$1:$F$11,5,FALSE),"Unknown Item") -> John Smith | N16: =IFERROR(VLOOKUP(C16:C60,Customer_database!$A$1:$F$11,4,FALSE),"Unknown Item") -> Gold | O16: =(E16*K16) -> 225 | P16: =((L16-K16)*E16) -> 424.95 | Q16: =(F16-B16) -> 2 | R16: =IF(AND(Q16>5,G16="North"),"CRITICAL DELAY",IF(Q16>5,"Late","On Time")) -> On Time | S16: =OR(H16="WELCOME10",H16="FREESHIP") -> TRUE
A17: ORD-24-1001 | B17: 45294 | C17: C-001 | D17: P-500 | E17: 5 | F17: 45296 | G17: North | H17: WELCOME10 | I17: =VLOOKUP(D17,Product_Master!$A$1:$F$8,2,FALSE) -> Wireless Mouse X1 | J17: =VLOOKUP(D17,Product_Master!$A$1:$F$8,3,FALSE) -> Electronics | K17: =VLOOKUP(D17:D61,Product_Master!$A$1:$F$8,4,FALSE) -> 12.5 | L17: =VLOOKUP(D17:D61,Product_Master!$A$1:$F$8,5,FALSE) -> 39.99 | M17: =IFERROR(VLOOKUP(C17:C61,Customer_database!$A$1:$F$11,5,FALSE),"Unknown Item") -> John Smith | N17: =IFERROR(VLOOKUP(C17:C61,Customer_database!$A$1:$F$11,4,FALSE),"Unknown Item") -> Gold | O17: =(E17*K17) -> 62.5 | P17: =((L17-K17)*E17) -> 137.45 | Q17: =(F17-B17) -> 2 | R17: =IF(AND(Q17>5,G17="North"),"CRITICAL DELAY",IF(Q17>5,"Late","On Time")) -> On Time | S17: =OR(H17="WELCOME10",H17="FREESHIP") -> TRUE
A18: ORD-24-1002 | B18: 45295 | C18: C-003 | D18: P-502 | E18: 1 | F18: 45299 | G18: West | I18: =VLOOKUP(D18,Product_Master!$A$1:$F$8,2,FALSE) -> Ergo Office Chair | J18: =VLOOKUP(D18,Product_Master!$A$1:$F$8,3,FALSE) -> Furniture | K18: =VLOOKUP(D18:D62,Product_Master!$A$1:$F$8,4,FALSE) -> 85 | L18: =VLOOKUP(D18:D62,Product_Master!$A$1:$F$8,5,FALSE) -> 249.99 | M18: =IFERROR(VLOOKUP(C18:C62,Customer_database!$A$1:$F$11,5,FALSE),"Unknown Item") -> Emily Blunt | N18: =IFERROR(VLOOKUP(C18:C62,Customer_database!$A$1:$F$11,4,FALSE),"Unknown Item") -> Bronze | O18: =(E18*K18) -> 85 | P18: =((L18-K18)*E18) -> 164.99 | Q18: =(F18-B18) -> 4 | R18: =IF(AND(Q18>5,G18="North"),"CRITICAL DELAY",IF(Q18>5,"Late","On Time")) -> On Time | S18: =OR(H18="WELCOME10",H18="FREESHIP") -> FALSE
A19: ORD-24-1003 | B19: 45297 | C19: C-002 | D19: P-501 | E19: 10 | F19: 45305 | G19: East | H19: BULK25 | I19: =VLOOKUP(D19,Product_Master!$A$1:$F$8,2,FALSE) -> Mech Keyboard RGB | J19: =VLOOKUP(D19,Product_Master!$A$1:$F$8,3,FALSE) -> Electronics | K19: =VLOOKUP(D19:D63,Product_Master!$A$1:$F$8,4,FALSE) -> 45 | L19: =VLOOKUP(D19:D63,Product_Master!$A$1:$F$8,5,FALSE) -> 129.99 | M19: =IFERROR(VLOOKUP(C19:C63,Customer_database!$A$1:$F$11,5,FALSE),"Unknown Item") -> Sarah Connor | N19: =IFERROR(VLOOKUP(C19:C63,Customer_database!$A$1:$F$11,4,FALSE),"Unknown Item") -> Silver | O19: =(E19*K19) -> 450 | P19: =((L19-K19)*E19) -> 849.9 | Q19: =(F19-B19) -> 8 | R19: =IF(AND(Q19>5,G19="North"),"CRITICAL DELAY",IF(Q19>5,"Late","On Time")) -> Late | S19: =OR(H19="WELCOME10",H19="FREESHIP") -> FALSE
A20: ORD-24-1004 | B20: 45299 | C20: C-005 | D20: P-505 | E20: 2 | F20: 45300 | G20: North | I20: =VLOOKUP(D20,Product_Master!$A$1:$F$8,2,FALSE) -> Dual Monitor Arm | J20: =VLOOKUP(D20,Product_Master!$A$1:$F$8,3,FALSE) -> Electronics | K20: =VLOOKUP(D20:D64,Product_Master!$A$1:$F$8,4,FALSE) -> 25 | L20: =VLOOKUP(D20:D64,Product_Master!$A$1:$F$8,5,FALSE) -> 75 | M20: =IFERROR(VLOOKUP(C20:C64,Customer_database!$A$1:$F$11,5,FALSE),"Unknown Item") -> Dwight Schrute | N20: =IFERROR(VLOOKUP(C20:C64,Customer_database!$A$1:$F$11,4,FALSE),"Unknown Item") -> Silver | O20: =(E20*K20) -> 50 | P20: =((L20-K20)*E20) -> 100 | Q20: =(F20-B20) -> 1 | R20: =IF(AND(Q20>5,G20="North"),"CRITICAL DELAY",IF(Q20>5,"Late","On Time")) -> On Time | S20: =OR(H20="WELCOME10",H20="FREESHIP") -> FALSE
A21: ORD-24-1005 | B21: 45301 | C21: C-001 | D21: P-500 | E21: 1 | F21: 45303 | G21: North | H21: FREESHIP | I21: =VLOOKUP(D21,Product_Master!$A$1:$F$8,2,FALSE) -> Wireless Mouse X1 | J21: =VLOOKUP(D21,Product_Master!$A$1:$F$8,3,FALSE) -> Electronics | K21: =VLOOKUP(D21:D65,Product_Master!$A$1:$F$8,4,FALSE) -> 12.5 | L21: =VLOOKUP(D21:D65,Product_Master!$A$1:$F$8,5,FALSE) -> 39.99 | M21: =IFERROR(VLOOKUP(C21:C65,Customer_database!$A$1:$F$11,5,FALSE),"Unknown Item") -> John Smith | N21: =IFERROR(VLOOKUP(C21:C65,Customer_database!$A$1:$F$11,4,FALSE),"Unknown Item") -> Gold | O21: =(E21*K21) -> 12.5 | P21: =((L21-K21)*E21) -> 27.49 | Q21: =(F21-B21) -> 2 | R21: =IF(AND(Q21>5,G21="North"),"CRITICAL DELAY",IF(Q21>5,"Late","On Time")) -> On Time | S21: =OR(H21="WELCOME10",H21="FREESHIP") -> TRUE
A22: ORD-24-1006 | B22: 45303 | C22: C-004 | D22: P-503 | E22: 3 | F22: 45310 | G22: South | H22: WELCOME10 | I22: =VLOOKUP(D22,Product_Master!$A$1:$F$8,2,FALSE) -> Oak Standing Desk | J22: =VLOOKUP(D22,Product_Master!$A$1:$F$8,3,FALSE) -> Furniture | K22: =VLOOKUP(D22:D66,Product_Master!$A$1:$F$8,4,FALSE) -> 160 | L22: =VLOOKUP(D22:D66,Product_Master!$A$1:$F$8,5,FALSE) -> 450 | M22: =IFERROR(VLOOKUP(C22:C66,Customer_database!$A$1:$F$11,5,FALSE),"Unknown Item") -> Michael Scott | N22: =IFERROR(VLOOKUP(C22:C66,Customer_database!$A$1:$F$11,4,FALSE),"Unknown Item") -> Gold | O22: =(E22*K22) -> 480 | P22: =((L22-K22)*E22) -> 870 | Q22: =(F22-B22) -> 7 | R22: =IF(AND(Q22>5,G22="North"),"CRITICAL DELAY",IF(Q22>5,"Late","On Time")) -> Late | S22: =OR(H22="WELCOME10",H22="FREESHIP") -> TRUE
A23: ORD-24-1007 | B23: 45306 | C23: C-006 | D23: P-504 | E23: 4 | F23: 45313 | G23: West | I23: =VLOOKUP(D23,Product_Master!$A$1:$F$8,2,FALSE) -> Smart LED Lamp | J23: =VLOOKUP(D23,Product_Master!$A$1:$F$8,3,FALSE) -> Home Decor | K23: =VLOOKUP(D23:D67,Product_Master!$A$1:$F$8,4,FALSE) -> 15 | L23: =VLOOKUP(D23:D67,Product_Master!$A$1:$F$8,5,FALSE) -> 45 | M23: =IFERROR(VLOOKUP(C23:C67,Customer_database!$A$1:$F$11,5,FALSE),"Unknown Item") -> Jim Halpert | N23: =IFERROR(VLOOKUP(C23:C67,Customer_database!$A$1:$F$11,4,FALSE),"Unknown Item") -> Bronze | O23: =(E23*K23) -> 60 | P23: =((L23-K23)*E23) -> 120 | Q23: =(F23-B23) -> 7 | R23: =IF(AND(Q23>5,G23="North"),"CRITICAL DELAY",IF(Q23>5,"Late","On Time")) -> Late | S23: =OR(H23="WELCOME10",H23="FREESHIP") -> FALSE
A24: ORD-24-1008 | B24: 45307 | C24: C-002 | D24: P-501 | E24: 6 | F24: 45309 | G24: East | I24: =VLOOKUP(D24,Product_Master!$A$1:$F$8,2,FALSE) -> Mech Keyboard RGB | J24: =VLOOKUP(D24,Product_Master!$A$1:$F$8,3,FALSE) -> Electronics | K24: =VLOOKUP(D24:D68,Product_Master!$A$1:$F$8,4,FALSE) -> 45 | L24: =VLOOKUP(D24:D68,Product_Master!$A$1:$F$8,5,FALSE) -> 129.99 | M24: =IFERROR(VLOOKUP(C24:C68,Customer_database!$A$1:$F$11,5,FALSE),"Unknown Item") -> Sarah Connor | N24: =IFERROR(VLOOKUP(C24:C68,Customer_database!$A$1:$F$11,4,FALSE),"Unknown Item") -> Silver | O24: =(E24*K24) -> 270 | P24: =((L24-K24)*E24) -> 509.94 | Q24: =(F24-B24) -> 2 | R24: =IF(AND(Q24>5,G24="North"),"CRITICAL DELAY",IF(Q24>5,"Late","On Time")) -> On Time | S24: =OR(H24="WELCOME10",H24="FREESHIP") -> FALSE
A25: ORD-24-1009 | B25: 45309 | C25: C-008 | D25: P-502 | E25: 2 | F25: 45320 | G25: South | H25: LATE_SORRY | I25: =VLOOKUP(D25,Product_Master!$A$1:$F$8,2,FALSE) -> Ergo Office Chair | J25: =VLOOKUP(D25,Product_Master!$A$1:$F$8,3,FALSE) -> Furniture | K25: =VLOOKUP(D25:D69,Product_Master!$A$1:$F$8,4,FALSE) -> 85 | L25: =VLOOKUP(D25:D69,Product_Master!$A$1:$F$8,5,FALSE) -> 249.99 | M25: =IFERROR(VLOOKUP(C25:C69,Customer_database!$A$1:$F$11,5,FALSE),"Unknown Item") -> Ryan Howard | N25: =IFERROR(VLOOKUP(C25:C69,Customer_database!$A$1:$F$11,4,FALSE),"Unknown Item") -> Bronze | O25: =(E25*K25) -> 170 | P25: =((L25-K25)*E25) -> 329.98 | Q25: =(F25-B25) -> 11 | R25: =IF(AND(Q25>5,G25="North"),"CRITICAL DELAY",IF(Q25>5,"Late","On Time")) -> Late | S25: =OR(H25="WELCOME10",H25="FREESHIP") -> FALSE
A26: ORD-24-1010 | B26: 45311 | C26: C-003 | D26: P-505 | E26: 1 | F26: 45312 | G26: West | I26: =VLOOKUP(D26,Product_Master!$A$1:$F$8,2,FALSE) -> Dual Monitor Arm | J26: =VLOOKUP(D26,Product_Master!$A$1:$F$8,3,FALSE) -> Electronics | K26: =VLOOKUP(D26:D70,Product_Master!$A$1:$F$8,4,FALSE) -> 25 | L26: =VLOOKUP(D26:D70,Product_Master!$A$1:$F$8,5,FALSE) -> 75 | M26: =IFERROR(VLOOKUP(C26:C70,Customer_database!$A$1:$F$11,5,FALSE),"Unknown Item") -> Emily Blunt | N26: =IFERROR(VLOOKUP(C26:C70,Customer_database!$A$1:$F$11,4,FALSE),"Unknown Item") -> Bronze | O26: =(E26*K26) -> 25 | P26: =((L26-K26)*E26) -> 50 | Q26: =(F26-B26) -> 1 | R26: =IF(AND(Q26>5,G26="North"),"CRITICAL DELAY",IF(Q26>5,"Late","On Time")) -> On Time | S26: =OR(H26="WELCOME10",H26="FREESHIP") -> FALSE
A27: ORD-24-1011 | B27: 45313 | C27: C-009 | D27: P-500 | E27: 20 | F27: 45314 | G27: North | H27: BULK_VIP | I27: =VLOOKUP(D27,Product_Master!$A$1:$F$8,2,FALSE) -> Wireless Mouse X1 | J27: =VLOOKUP(D27,Product_Master!$A$1:$F$8,3,FALSE) -> Electronics | K27: =VLOOKUP(D27:D71,Product_Master!$A$1:$F$8,4,FALSE) -> 12.5 | L27: =VLOOKUP(D27:D71,Product_Master!$A$1:$F$8,5,FALSE) -> 39.99 | M27: =IFERROR(VLOOKUP(C27:C71,Customer_database!$A$1:$F$11,5,FALSE),"Unknown Item") -> Creed Bratton | N27: =IFERROR(VLOOKUP(C27:C71,Customer_database!$A$1:$F$11,4,FALSE),"Unknown Item") -> Gold | O27: =(E27*K27) -> 250 | P27: =((L27-K27)*E27) -> 549.8 | Q27: =(F27-B27) -> 1 | R27: =IF(AND(Q27>5,G27="North"),"CRITICAL DELAY",IF(Q27>5,"Late","On Time")) -> On Time | S27: =OR(H27="WELCOME10",H27="FREESHIP") -> FALSE
A28: ORD-24-1012 | B28: 45316 | C28: C-007 | D28: P-502 | E28: 3 | F28: 45327 | G28: East | I28: =VLOOKUP(D28,Product_Master!$A$1:$F$8,2,FALSE) -> Ergo Office Chair | J28: =VLOOKUP(D28,Product_Master!$A$1:$F$8,3,FALSE) -> Furniture | K28: =VLOOKUP(D28:D72,Product_Master!$A$1:$F$8,4,FALSE) -> 85 | L28: =VLOOKUP(D28:D72,Product_Master!$A$1:$F$8,5,FALSE) -> 249.99 | M28: =IFERROR(VLOOKUP(C28:C72,Customer_database!$A$1:$F$11,5,FALSE),"Unknown Item") -> Pam Beesly | N28: =IFERROR(VLOOKUP(C28:C72,Customer_database!$A$1:$F$11,4,FALSE),"Unknown Item") -> Silver | O28: =(E28*K28) -> 255 | P28: =((L28-K28)*E28) -> 494.97 | Q28: =(F28-B28) -> 11 | R28: =IF(AND(Q28>5,G28="North"),"CRITICAL DELAY",IF(Q28>5,"Late","On Time")) -> Late | S28: =OR(H28="WELCOME10",H28="FREESHIP") -> FALSE
A29: ORD-24-1013 | B29: 45317 | C29: C-010 | D29: P-503 | E29: 2 | F29: 45319 | G29: South | H29: WELCOME10 | I29: =VLOOKUP(D29,Product_Master!$A$1:$F$8,2,FALSE) -> Oak Standing Desk | J29: =VLOOKUP(D29,Product_Master!$A$1:$F$8,3,FALSE) -> Furniture | K29: =VLOOKUP(D29:D73,Product_Master!$A$1:$F$8,4,FALSE) -> 160 | L29: =VLOOKUP(D29:D73,Product_Master!$A$1:$F$8,5,FALSE) -> 450 | M29: =IFERROR(VLOOKUP(C29:C73,Customer_database!$A$1:$F$11,5,FALSE),"Unknown Item") -> Stanley Hudson | N29: =IFERROR(VLOOKUP(C29:C73,Customer_database!$A$1:$F$11,4,FALSE),"Unknown Item") -> Silver | O29: =(E29*K29) -> 320 | P29: =((L29-K29)*E29) -> 580 | Q29: =(F29-B29) -> 2 | R29: =IF(AND(Q29>5,G29="North"),"CRITICAL DELAY",IF(Q29>5,"Late","On Time")) -> On Time | S29: =OR(H29="WELCOME10",H29="FREESHIP") -> TRUE
A30: ORD-24-1014 | B30: 45319 | C30: C-005 | D30: P-504 | E30: 1 | F30: 45324 | G30: North | I30: =VLOOKUP(D30,Product_Master!$A$1:$F$8,2,FALSE) -> Smart LED Lamp | J30: =VLOOKUP(D30,Product_Master!$A$1:$F$8,3,FALSE) -> Home Decor | K30: =VLOOKUP(D30:D74,Product_Master!$A$1:$F$8,4,FALSE) -> 15 | L30: =VLOOKUP(D30:D74,Product_Master!$A$1:$F$8,5,FALSE) -> 45 | M30: =IFERROR(VLOOKUP(C30:C74,Customer_database!$A$1:$F$11,5,FALSE),"Unknown Item") -> Dwight Schrute | N30: =IFERROR(VLOOKUP(C30:C74,Customer_database!$A$1:$F$11,4,FALSE),"Unknown Item") -> Silver | O30: =(E30*K30) -> 15 | P30: =((L30-K30)*E30) -> 30 | Q30: =(F30-B30) -> 5 | R30: =IF(AND(Q30>5,G30="North"),"CRITICAL DELAY",IF(Q30>5,"Late","On Time")) -> On Time | S30: =OR(H30="WELCOME10",H30="FREESHIP") -> FALSE
A31: ORD-24-1015 | B31: 45321 | C31: C-001 | D31: P-501 | E31: 5 | F31: 45323 | G31: North | H31: FREESHIP | I31: =VLOOKUP(D31,Product_Master!$A$1:$F$8,2,FALSE) -> Mech Keyboard RGB | J31: =VLOOKUP(D31,Product_Master!$A$1:$F$8,3,FALSE) -> Electronics | K31: =VLOOKUP(D31:D75,Product_Master!$A$1:$F$8,4,FALSE) -> 45 | L31: =VLOOKUP(D31:D75,Product_Master!$A$1:$F$8,5,FALSE) -> 129.99 | M31: =IFERROR(VLOOKUP(C31:C75,Customer_database!$A$1:$F$11,5,FALSE),"Unknown Item") -> John Smith | N31: =IFERROR(VLOOKUP(C31:C75,Customer_database!$A$1:$F$11,4,FALSE),"Unknown Item") -> Gold | O31: =(E31*K31) -> 225 | P31: =((L31-K31)*E31) -> 424.95 | Q31: =(F31-B31) -> 2 | R31: =IF(AND(Q31>5,G31="North"),"CRITICAL DELAY",IF(Q31>5,"Late","On Time")) -> On Time | S31: =OR(H31="WELCOME10",H31="FREESHIP") -> TRUE
A32: ORD-24-1001 | B32: 45294 | C32: C-001 | D32: P-500 | E32: 5 | F32: 45296 | G32: North | H32: WELCOME10 | I32: =VLOOKUP(D32,Product_Master!$A$1:$F$8,2,FALSE) -> Wireless Mouse X1 | J32: =VLOOKUP(D32,Product_Master!$A$1:$F$8,3,FALSE) -> Electronics | K32: =VLOOKUP(D32:D76,Product_Master!$A$1:$F$8,4,FALSE) -> 12.5 | L32: =VLOOKUP(D32:D76,Product_Master!$A$1:$F$8,5,FALSE) -> 39.99 | M32: =IFERROR(VLOOKUP(C32:C76,Customer_database!$A$1:$F$11,5,FALSE),"Unknown Item") -> John Smith | N32: =IFERROR(VLOOKUP(C32:C76,Customer_database!$A$1:$F$11,4,FALSE),"Unknown Item") -> Gold | O32: =(E32*K32) -> 62.5 | P32: =((L32-K32)*E32) -> 137.45 | Q32: =(F32-B32) -> 2 | R32: =IF(AND(Q32>5,G32="North"),"CRITICAL DELAY",IF(Q32>5,"Late","On Time")) -> On Time | S32: =OR(H32="WELCOME10",H32="FREESHIP") -> TRUE
A33: ORD-24-1002 | B33: 45295 | C33: C-003 | D33: P-502 | E33: 1 | F33: 45299 | G33: West | I33: =VLOOKUP(D33,Product_Master!$A$1:$F$8,2,FALSE) -> Ergo Office Chair | J33: =VLOOKUP(D33,Product_Master!$A$1:$F$8,3,FALSE) -> Furniture | K33: =VLOOKUP(D33:D77,Product_Master!$A$1:$F$8,4,FALSE) -> 85 | L33: =VLOOKUP(D33:D77,Product_Master!$A$1:$F$8,5,FALSE) -> 249.99 | M33: =IFERROR(VLOOKUP(C33:C77,Customer_database!$A$1:$F$11,5,FALSE),"Unknown Item") -> Emily Blunt | N33: =IFERROR(VLOOKUP(C33:C77,Customer_database!$A$1:$F$11,4,FALSE),"Unknown Item") -> Bronze | O33: =(E33*K33) -> 85 | P33: =((L33-K33)*E33) -> 164.99 | Q33: =(F33-B33) -> 4 | R33: =IF(AND(Q33>5,G33="North"),"CRITICAL DELAY",IF(Q33>5,"Late","On Time")) -> On Time | S33: =OR(H33="WELCOME10",H33="FREESHIP") -> FALSE
A34: ORD-24-1003 | B34: 45297 | C34: C-002 | D34: P-501 | E34: 10 | F34: 45305 | G34: East | H34: BULK25 | I34: =VLOOKUP(D34,Product_Master!$A$1:$F$8,2,FALSE) -> Mech Keyboard RGB | J34: =VLOOKUP(D34,Product_Master!$A$1:$F$8,3,FALSE) -> Electronics | K34: =VLOOKUP(D34:D78,Product_Master!$A$1:$F$8,4,FALSE) -> 45 | L34: =VLOOKUP(D34:D78,Product_Master!$A$1:$F$8,5,FALSE) -> 129.99 | M34: =IFERROR(VLOOKUP(C34:C78,Customer_database!$A$1:$F$11,5,FALSE),"Unknown Item") -> Sarah Connor | N34: =IFERROR(VLOOKUP(C34:C78,Customer_database!$A$1:$F$11,4,FALSE),"Unknown Item") -> Silver | O34: =(E34*K34) -> 450 | P34: =((L34-K34)*E34) -> 849.9 | Q34: =(F34-B34) -> 8 | R34: =IF(AND(Q34>5,G34="North"),"CRITICAL DELAY",IF(Q34>5,"Late","On Time")) -> Late | S34: =OR(H34="WELCOME10",H34="FREESHIP") -> FALSE
A35: ORD-24-1004 | B35: 45299 | C35: C-005 | D35: P-505 | E35: 2 | F35: 45300 | G35: North | I35: =VLOOKUP(D35,Product_Master!$A$1:$F$8,2,FALSE) -> Dual Monitor Arm | J35: =VLOOKUP(D35,Product_Master!$A$1:$F$8,3,FALSE) -> Electronics | K35: =VLOOKUP(D35:D79,Product_Master!$A$1:$F$8,4,FALSE) -> 25 | L35: =VLOOKUP(D35:D79,Product_Master!$A$1:$F$8,5,FALSE) -> 75 | M35: =IFERROR(VLOOKUP(C35:C79,Customer_database!$A$1:$F$11,5,FALSE),"Unknown Item") -> Dwight Schrute | N35: =IFERROR(VLOOKUP(C35:C79,Customer_database!$A$1:$F$11,4,FALSE),"Unknown Item") -> Silver | O35: =(E35*K35) -> 50 | P35: =((L35-K35)*E35) -> 100 | Q35: =(F35-B35) -> 1 | R35: =IF(AND(Q35>5,G35="North"),"CRITICAL DELAY",IF(Q35>5,"Late","On Time")) -> On Time | S35: =OR(H35="WELCOME10",H35="FREESHIP") -> FALSE
A36: ORD-24-1005 | B36: 45301 | C36: C-001 | D36: P-500 | E36: 1 | F36: 45303 | G36: North | H36: FREESHIP | I36: =VLOOKUP(D36,Product_Master!$A$1:$F$8,2,FALSE) -> Wireless Mouse X1 | J36: =VLOOKUP(D36,Product_Master!$A$1:$F$8,3,FALSE) -> Electronics | K36: =VLOOKUP(D36:D80,Product_Master!$A$1:$F$8,4,FALSE) -> 12.5 | L36: =VLOOKUP(D36:D80,Product_Master!$A$1:$F$8,5,FALSE) -> 39.99 | M36: =IFERROR(VLOOKUP(C36:C80,Customer_database!$A$1:$F$11,5,FALSE),"Unknown Item") -> John Smith | N36: =IFERROR(VLOOKUP(C36:C80,Customer_database!$A$1:$F$11,4,FALSE),"Unknown Item") -> Gold | O36: =(E36*K36) -> 12.5 | P36: =((L36-K36)*E36) -> 27.49 | Q36: =(F36-B36) -> 2 | R36: =IF(AND(Q36>5,G36="North"),"CRITICAL DELAY",IF(Q36>5,"Late","On Time")) -> On Time | S36: =OR(H36="WELCOME10",H36="FREESHIP") -> TRUE
A37: ORD-24-1006 | B37: 45303 | C37: C-004 | D37: P-503 | E37: 3 | F37: 45310 | G37: South | H37: WELCOME10 | I37: =VLOOKUP(D37,Product_Master!$A$1:$F$8,2,FALSE) -> Oak Standing Desk | J37: =VLOOKUP(D37,Product_Master!$A$1:$F$8,3,FALSE) -> Furniture | K37: =VLOOKUP(D37:D81,Product_Master!$A$1:$F$8,4,FALSE) -> 160 | L37: =VLOOKUP(D37:D81,Product_Master!$A$1:$F$8,5,FALSE) -> 450 | M37: =IFERROR(VLOOKUP(C37:C81,Customer_database!$A$1:$F$11,5,FALSE),"Unknown Item") -> Michael Scott | N37: =IFERROR(VLOOKUP(C37:C81,Customer_database!$A$1:$F$11,4,FALSE),"Unknown Item") -> Gold | O37: =(E37*K37) -> 480 | P37: =((L37-K37)*E37) -> 870 | Q37: =(F37-B37) -> 7 | R37: =IF(AND(Q37>5,G37="North"),"CRITICAL DELAY",IF(Q37>5,"Late","On Time")) -> Late | S37: =OR(H37="WELCOME10",H37="FREESHIP") -> TRUE
A38: ORD-24-1007 | B38: 45306 | C38: C-006 | D38: P-504 | E38: 4 | F38: 45313 | G38: West | I38: =VLOOKUP(D38,Product_Master!$A$1:$F$8,2,FALSE) -> Smart LED Lamp | J38: =VLOOKUP(D38,Product_Master!$A$1:$F$8,3,FALSE) -> Home Decor | K38: =VLOOKUP(D38:D82,Product_Master!$A$1:$F$8,4,FALSE) -> 15 | L38: =VLOOKUP(D38:D82,Product_Master!$A$1:$F$8,5,FALSE) -> 45 | M38: =IFERROR(VLOOKUP(C38:C82,Customer_database!$A$1:$F$11,5,FALSE),"Unknown Item") -> Jim Halpert | N38: =IFERROR(VLOOKUP(C38:C82,Customer_database!$A$1:$F$11,4,FALSE),"Unknown Item") -> Bronze | O38: =(E38*K38) -> 60 | P38: =((L38-K38)*E38) -> 120 | Q38: =(F38-B38) -> 7 | R38: =IF(AND(Q38>5,G38="North"),"CRITICAL DELAY",IF(Q38>5,"Late","On Time")) -> Late | S38: =OR(H38="WELCOME10",H38="FREESHIP") -> FALSE
A39: ORD-24-1008 | B39: 45307 | C39: C-002 | D39: P-501 | E39: 6 | F39: 45309 | G39: East | I39: =VLOOKUP(D39,Product_Master!$A$1:$F$8,2,FALSE) -> Mech Keyboard RGB | J39: =VLOOKUP(D39,Product_Master!$A$1:$F$8,3,FALSE) -> Electronics | K39: =VLOOKUP(D39:D83,Product_Master!$A$1:$F$8,4,FALSE) -> 45 | L39: =VLOOKUP(D39:D83,Product_Master!$A$1:$F$8,5,FALSE) -> 129.99 | M39: =IFERROR(VLOOKUP(C39:C83,Customer_database!$A$1:$F$11,5,FALSE),"Unknown Item") -> Sarah Connor | N39: =IFERROR(VLOOKUP(C39:C83,Customer_database!$A$1:$F$11,4,FALSE),"Unknown Item") -> Silver | O39: =(E39*K39) -> 270 | P39: =((L39-K39)*E39) -> 509.94 | Q39: =(F39-B39) -> 2 | R39: =IF(AND(Q39>5,G39="North"),"CRITICAL DELAY",IF(Q39>5,"Late","On Time")) -> On Time | S39: =OR(H39="WELCOME10",H39="FREESHIP") -> FALSE
A40: ORD-24-1009 | B40: 45309 | C40: C-008 | D40: P-502 | E40: 2 | F40: 45320 | G40: South | H40: LATE_SORRY | I40: =VLOOKUP(D40,Product_Master!$A$1:$F$8,2,FALSE) -> Ergo Office Chair | J40: =VLOOKUP(D40,Product_Master!$A$1:$F$8,3,FALSE) -> Furniture | K40: =VLOOKUP(D40:D84,Product_Master!$A$1:$F$8,4,FALSE) -> 85 | L40: =VLOOKUP(D40:D84,Product_Master!$A$1:$F$8,5,FALSE) -> 249.99 | M40: =IFERROR(VLOOKUP(C40:C84,Customer_database!$A$1:$F$11,5,FALSE),"Unknown Item") -> Ryan Howard | N40: =IFERROR(VLOOKUP(C40:C84,Customer_database!$A$1:$F$11,4,FALSE),"Unknown Item") -> Bronze | O40: =(E40*K40) -> 170 | P40: =((L40-K40)*E40) -> 329.98 | Q40: =(F40-B40) -> 11 | R40: =IF(AND(Q40>5,G40="North"),"CRITICAL DELAY",IF(Q40>5,"Late","On Time")) -> Late | S40: =OR(H40="WELCOME10",H40="FREESHIP") -> FALSE
...

Sheet Pivot
A1: Total Profit by Product Category
A3: Row Labels | B3: Sum of Total Profit | D3: Sum of Total Revenew
A4: Dual Monitor Arm | B4: 450 | D4: 8190
A5: Ergo Office Chair | B5: 2969.82
A6: Mech Keyboard RGB | B6: 5354.37
A7: Oak Standing Desk | B7: 4350 | D7: Sum of Total Profit
A8: Smart LED Lamp | B8: 450 | D8: 15718.41
A9: Wireless Mouse X1 | B9: 2144.22
A10: Grand Total | B10: 15718.41 | D10: Profit margin
A11: Total Revenue by Membership Tier | D11: =GETPIVOTDATA("Total Profit",$D$7)/GETPIVOTDATA("Total Revenew",$D$3) -> 1.9192198
A13: Row Labels | B13: Sum of Total Revenew | D13: On time orders
A14: Bronze | B14: 1020 | D14: =COUNTIF(Raw_orders!R2:R46,"On Time") / COUNTA(Raw_orders!R2:R46) -> 0.66666667
A15: Gold | B15: 3090
A16: Silver | B16: 4080
A17: Grand Total | B17: 8190
A20: Count of "Critical Delays" by Region.
A21: Count of Status | B21: Column Labels
A22: Row Labels | B22: Late | C22: On Time | D22: Grand Total
A23: East | B23: 6 | C23: 3 | D23: 9
A24: North | C24: 18 | D24: 18
A25: South | B25: 6 | C25: 3 | D25: 9
A26: West | B26: 3 | C26: 6 | D26: 9
A27: Grand Total | B27: 15 | C27: 30 | D27: 45

Sheet Executive_Dashboard
P5: Total Revenue :
P10: Total Profit :
P15: Profit Margin % :
P20: On-Time Delivery :

Sheet Product_Master
A1: Prod_ID | B1: Product_Name | C1: Category | D1: Unit_Cost | E1: Unit_Price | F1: Supplier
A2: P-500 | B2: Wireless Mouse X1 | C2: Electronics | D2: 12.5 | E2: 39.99 | F2: TechGiant
A3: P-501 | B3: Mech Keyboard RGB | C3: Electronics | D3: 45 | E3: 129.99 | F3: KeyWorld
A4: P-502 | B4: Ergo Office Chair | C4: Furniture | D4: 85 | E4: 249.99 | F4: SitRight
A5: P-503 | B5: Oak Standing Desk | C5: Furniture | D5: 160 | E5: 450 | F5: WoodWorks
A6: P-504 | B6: Smart LED Lamp | C6: Home Decor | D6: 15 | E6: 45 | F6: BrightLite
A7: P-505 | B7: Dual Monitor Arm | C7: Electronics | D7: 25 | E7: 75 | F7: TechGiant
A8: P-999 | B8: Extended Warranty | C8: Services | D8: 5 | E8: 25 | F8: ApexLogistics

Sheet Customer_database
A1: Cust_ID | B1: Customer_Raw_Name | C1: Email_Address | D1: Membership_Tier | E1: Clean_Name | F1: Email_Domain
A2: C-001 | B2: john smith | C2: j.smith@gmail.com | D2: Gold | E2: =PROPER(TRIM(B2)) -> John Smith | F2: =MID(C2,FIND("@",C2)+1,LEN(C2)) -> gmail.com
A3: C-002 | B3: SARAH CONNOR | C3: s.connor@skynet.org | D3: Silver | E3: =PROPER(TRIM(B3)) -> Sarah Connor | F3: =MID(C3,FIND("@",C3)+1,LEN(C3)) -> skynet.org
A4: C-003 | B4: emily blunt | C4: e.blunt@studio.net | D4: Bronze | E4: =PROPER(TRIM(B4)) -> Emily Blunt | F4: =MID(C4,FIND("@",C4)+1,LEN(C4)) -> studio.net
A5: C-004 | B5: MICHAEL scott | C5: m.scott@paperco.com | D5: Gold | E5: =PROPER(TRIM(B5)) -> Michael Scott | F5: =MID(C5,FIND("@",C5)+1,LEN(C5)) -> paperco.com
A6: C-005 | B6: dwight Schrute | C6: beets@farms.com | D6: Silver | E6: =PROPER(TRIM(B6)) -> Dwight Schrute | F6: =MID(C6,FIND("@",C6)+1,LEN(C6)) -> farms.com
A7: C-006 | B7: jim HALPERT | C7: jim@paperco.com | D7: Bronze | E7: =PROPER(TRIM(B7)) -> Jim Halpert | F7: =MID(C7,FIND("@",C7)+1,LEN(C7)) -> paperco.com
A8: C-007 | B8: pam beesly | C8: art@paperco.com | D8: Silver | E8: =PROPER(TRIM(B8)) -> Pam Beesly | F8: =MID(C8,FIND("@",C8)+1,LEN(C8)) -> paperco.com
A9: C-008 | B9: ryan howard | C9: temp@agency.com | D9: Bronze | E9: =PROPER(TRIM(B9)) -> Ryan Howard | F9: =MID(C9,FIND("@",C9)+1,LEN(C9)) -> agency.com
A10: C-009 | B10: Creed Bratton | C10: unknown@unknown.com | D10: Gold | E10: =PROPER(TRIM(B10)) -> Creed Bratton | F10: =MID(C10,FIND("@",C10)+1,LEN(C10)) -> unknown.com
A11: C-010 | B11: stanley hudson | C11: crossword@paperco.com | D11: Silver | E11: =PROPER(TRIM(B11)) -> Stanley Hudson | F11: =MID(C11,FIND("@",C11)+1,LEN(C11)) -> paperco.com
